<sdf version='1.7'>
  <model name='ackermann_steering_vehicle'>
    <link name='base_link'>
      <inertial>
        <pose>0 0 0 0 -0 0</pose>
        <mass>1000</mass>
        <inertia>
          <ixx>104.167</ixx>
          <ixy>-1.35e-06</ixy>
          <ixz>-2.025e-05</ixz>
          <iyy>354.167</iyy>
          <iyz>-1.125e-06</iyz>
          <izz>416.667</izz>
        </inertia>
      </inertial>
      <collision name='base_link_collision'>
        <pose>0 0 0 0 -0 0</pose>
        <geometry>
          <box>
            <size>2 1 0.5</size>
          </box>
        </geometry>
        <surface>
          <contact>
            <ode/>
          </contact>
          <friction>
            <ode>
              <mu>0.0001</mu>
              <mu2>0.0001</mu2>
            </ode>
          </friction>
        </surface>
      </collision>
      <collision name='base_link_fixed_joint_lump__camera_stick_link_collision_1'>
        <pose>0.9 0.15 0.75 0 -0 0</pose>
        <geometry>
          <box>
            <size>0.2 0.2 1.5</size>
          </box>
        </geometry>
      </collision>
      <collision name='base_link_fixed_joint_lump__camera_link_collision_2'>
        <pose>0.9 0 1.5 0 0.1 0</pose>
        <geometry>
          <box>
            <size>0.1 0.1 0.1</size>
          </box>
        </geometry>
        <surface>
          <contact>
            <ode/>
          </contact>
          <friction>
            <ode/>
          </friction>
        </surface>
      </collision>
      <visual name='base_link_visual'>
        <pose>0 0 0 0 -0 0</pose>
        <geometry>
          <box>
            <size>2 1 0.5</size>
          </box>
        </geometry>
      </visual>
      <visual name='base_link_fixed_joint_lump__camera_stick_link_visual_1'>
        <pose>0.9 0.15 0.75 0 -0 0</pose>
        <geometry>
          <box>
            <size>0.2 0.2 1.5</size>
          </box>
        </geometry>
      </visual>
      <visual name='base_link_fixed_joint_lump__camera_link_visual_2'>
        <pose>0.9 0 1.5 0 0.1 0</pose>
        <geometry>
          <box>
            <size>0.1 0.1 0.1</size>
          </box>
        </geometry>
      </visual>
      <sensor name='vehicle_front_camera' type='camera'>
        <update_rate>30</update_rate>
        <visualize>1</visualize>
        <topic>camera</topic>
        <camera name='head'>
          <horizontal_fov>90</horizontal_fov>
          <image>
            <width>640</width>
            <height>480</height>
            <format>R8G8B8</format>
          </image>
          <clip>
            <near>0.02</near>
            <far>300</far>
          </clip>
          <noise>
            <type>gaussian</type>
            <mean>0</mean>
            <stddev>0.007</stddev>
          </noise>
        </camera>
        <plugin name='camera_controller' filename='libgazebo_ros_camera.so'>
          <alwaysOn>1</alwaysOn>
          <updateRate>0.0</updateRate>
          <cameraName>vehicle_front_camera</cameraName>
          <frameName>camera_link</frameName>
          <hackBaseline>0.07</hackBaseline>
          <distortionK1>0.0</distortionK1>
          <distortionK2>0.0</distortionK2>
          <distortionK3>0.0</distortionK3>
          <distortionT1>0.0</distortionT1>
          <distortionT2>0.0</distortionT2>
        </plugin>
        <pose>0.9 0 1.5 0 0.1 0</pose>
      </sensor>
    </link>
    <joint name='front_left_steering_joint' type='revolute'>
      <pose relative_to='base_link'>0.7 0.55 -0.15 0 -0 0</pose>
      <parent>base_link</parent>
      <child>front_left_steering_link</child>
      <axis>
        <xyz>0 0 1</xyz>
        <limit>
          <lower>-0.6108</lower>
          <upper>0.6108</upper>
          <effort>1</effort>
          <velocity>1.5708</velocity>
        </limit>
        <dynamics>
          <damping>0.1</damping>
          <friction>0.1</friction>
          <spring_reference>0</spring_reference>
          <spring_stiffness>0</spring_stiffness>
        </dynamics>
      </axis>
    </joint>
    <link name='front_left_steering_link'>
      <pose relative_to='front_left_steering_joint'>0 0 0 0 -0 0</pose>
      <inertial>
        <pose>0 0 0 1.57079 -0 0</pose>
        <mass>0.01</mass>
        <inertia>
          <ixx>0</ixx>
          <ixy>0</ixy>
          <ixz>0</ixz>
          <iyy>0</iyy>
          <iyz>0</iyz>
          <izz>0</izz>
        </inertia>
      </inertial>
      <collision name='front_left_steering_link_collision'>
        <pose>0 0 0 1.57079 -0 0</pose>
        <geometry>
          <cylinder>
            <length>0.001</length>
            <radius>0.01</radius>
          </cylinder>
        </geometry>
      </collision>
      <visual name='front_left_steering_link_visual'>
        <pose>0 0 0 1.57079 -0 0</pose>
        <geometry>
          <cylinder>
            <length>0.001</length>
            <radius>0.01</radius>
          </cylinder>
        </geometry>
      </visual>
    </link>
    <joint name='front_left_wheel_joint' type='revolute'>
      <pose relative_to='front_left_steering_link'>0 0 0 0 -0 0</pose>
      <parent>front_left_steering_link</parent>
      <child>front_left_wheel_link</child>
      <axis>
        <xyz>0 1 0</xyz>
        <limit>
          <effort>10</effort>
          <velocity>3.33333</velocity>
          <lower>-1e+16</lower>
          <upper>1e+16</upper>
        </limit>
        <dynamics>
          <damping>0.1</damping>
          <friction>0.1</friction>
          <spring_reference>0</spring_reference>
          <spring_stiffness>0</spring_stiffness>
        </dynamics>
      </axis>
    </joint>
    <link name='front_left_wheel_link'>
      <pose relative_to='front_left_wheel_joint'>0 0 0 0 -0 0</pose>
      <inertial>
        <pose>0 0 0 1.57079 -0 0</pose>
        <mass>28.2743</mass>
        <inertia>
          <ixx>0.659734</ixx>
          <ixy>0</ixy>
          <ixz>0</ixz>
          <iyy>0.659734</iyy>
          <iyz>0</iyz>
          <izz>1.27235</izz>
        </inertia>
      </inertial>
      <collision name='front_left_wheel_link_collision'>
        <pose>0 0 0 1.57079 -0 0</pose>
        <geometry>
          <cylinder>
            <length>0.1</length>
            <radius>0.3</radius>
          </cylinder>
        </geometry>
        <surface>
          <contact>
            <ode/>
          </contact>
          <friction>
            <ode>
              <mu>100</mu>
              <mu2>100</mu2>
            </ode>
          </friction>
        </surface>
      </collision>
      <visual name='front_left_wheel_link_visual'>
        <pose>0 0 0 1.57079 -0 0</pose>
        <geometry>
          <cylinder>
            <length>0.1</length>
            <radius>0.3</radius>
          </cylinder>
        </geometry>
      </visual>
    </link>
    <joint name='front_right_steering_joint' type='revolute'>
      <pose relative_to='base_link'>0.7 -0.55 -0.15 0 -0 0</pose>
      <parent>base_link</parent>
      <child>front_right_steering_link</child>
      <axis>
        <xyz>0 0 1</xyz>
        <limit>
          <lower>-0.6108</lower>
          <upper>0.6108</upper>
          <effort>1</effort>
          <velocity>1.5708</velocity>
        </limit>
        <dynamics>
          <damping>0.1</damping>
          <friction>0.1</friction>
          <spring_reference>0</spring_reference>
          <spring_stiffness>0</spring_stiffness>
        </dynamics>
      </axis>
    </joint>
    <link name='front_right_steering_link'>
      <pose relative_to='front_right_steering_joint'>0 0 0 0 -0 0</pose>
      <inertial>
        <pose>0 0 0 1.57079 -0 0</pose>
        <mass>0.01</mass>
        <inertia>
          <ixx>0</ixx>
          <ixy>0</ixy>
          <ixz>0</ixz>
          <iyy>0</iyy>
          <iyz>0</iyz>
          <izz>0</izz>
        </inertia>
      </inertial>
      <collision name='front_right_steering_link_collision'>
        <pose>0 0 0 1.57079 -0 0</pose>
        <geometry>
          <cylinder>
            <length>0.001</length>
            <radius>0.01</radius>
          </cylinder>
        </geometry>
      </collision>
      <visual name='front_right_steering_link_visual'>
        <pose>0 0 0 1.57079 -0 0</pose>
        <geometry>
          <cylinder>
            <length>0.001</length>
            <radius>0.01</radius>
          </cylinder>
        </geometry>
      </visual>
    </link>
    <joint name='front_right_wheel_joint' type='revolute'>
      <pose relative_to='front_right_steering_link'>0 0 0 0 -0 0</pose>
      <parent>front_right_steering_link</parent>
      <child>front_right_wheel_link</child>
      <axis>
        <xyz>0 1 0</xyz>
        <limit>
          <effort>10</effort>
          <velocity>3.33333</velocity>
          <lower>-1e+16</lower>
          <upper>1e+16</upper>
        </limit>
        <dynamics>
          <damping>0.1</damping>
          <friction>0.1</friction>
          <spring_reference>0</spring_reference>
          <spring_stiffness>0</spring_stiffness>
        </dynamics>
      </axis>
    </joint>
    <link name='front_right_wheel_link'>
      <pose relative_to='front_right_wheel_joint'>0 0 0 0 -0 0</pose>
      <inertial>
        <pose>0 0 0 1.57079 -0 0</pose>
        <mass>28.2743</mass>
        <inertia>
          <ixx>0.659734</ixx>
          <ixy>0</ixy>
          <ixz>0</ixz>
          <iyy>0.659734</iyy>
          <iyz>0</iyz>
          <izz>1.27235</izz>
        </inertia>
      </inertial>
      <collision name='front_right_wheel_link_collision'>
        <pose>0 0 0 1.57079 -0 0</pose>
        <geometry>
          <cylinder>
            <length>0.1</length>
            <radius>0.3</radius>
          </cylinder>
        </geometry>
        <surface>
          <contact>
            <ode/>
          </contact>
          <friction>
            <ode>
              <mu>100</mu>
              <mu2>100</mu2>
            </ode>
          </friction>
        </surface>
      </collision>
      <visual name='front_right_wheel_link_visual'>
        <pose>0 0 0 1.57079 -0 0</pose>
        <geometry>
          <cylinder>
            <length>0.1</length>
            <radius>0.3</radius>
          </cylinder>
        </geometry>
      </visual>
    </link>
    <joint name='rear_left_wheel_joint' type='revolute'>
      <pose relative_to='base_link'>-0.7 0.55 -0.15 0 -0 0</pose>
      <parent>base_link</parent>
      <child>rear_left_wheel_link</child>
      <axis>
        <xyz>0 1 0</xyz>
        <limit>
          <effort>10</effort>
          <velocity>3.33333</velocity>
          <lower>-1e+16</lower>
          <upper>1e+16</upper>
        </limit>
        <dynamics>
          <damping>0.1</damping>
          <friction>0.1</friction>
          <spring_reference>0</spring_reference>
          <spring_stiffness>0</spring_stiffness>
        </dynamics>
      </axis>
    </joint>
    <link name='rear_left_wheel_link'>
      <pose relative_to='rear_left_wheel_joint'>0 0 0 0 -0 0</pose>
      <inertial>
        <pose>0 0 0 1.57079 -0 0</pose>
        <mass>2</mass>
        <inertia>
          <ixx>0.659734</ixx>
          <ixy>0</ixy>
          <ixz>0</ixz>
          <iyy>0.659734</iyy>
          <iyz>0</iyz>
          <izz>1.27235</izz>
        </inertia>
      </inertial>
      <collision name='rear_left_wheel_link_collision'>
        <pose>0 0 0 1.57079 -0 0</pose>
        <geometry>
          <cylinder>
            <length>0.1</length>
            <radius>0.3</radius>
          </cylinder>
        </geometry>
        <surface>
          <contact>
            <ode/>
          </contact>
          <friction>
            <ode>
              <mu>100</mu>
              <mu2>100</mu2>
            </ode>
          </friction>
        </surface>
      </collision>
      <visual name='rear_left_wheel_link_visual'>
        <pose>0 0 0 1.57079 -0 0</pose>
        <geometry>
          <cylinder>
            <length>0.1</length>
            <radius>0.3</radius>
          </cylinder>
        </geometry>
      </visual>
    </link>
    <joint name='rear_right_wheel_joint' type='revolute'>
      <pose relative_to='base_link'>-0.7 -0.55 -0.15 0 -0 0</pose>
      <parent>base_link</parent>
      <child>rear_right_wheel_link</child>
      <axis>
        <xyz>0 1 0</xyz>
        <limit>
          <effort>10</effort>
          <velocity>3.33333</velocity>
          <lower>-1e+16</lower>
          <upper>1e+16</upper>
        </limit>
        <dynamics>
          <damping>0.1</damping>
          <friction>0.1</friction>
          <spring_reference>0</spring_reference>
          <spring_stiffness>0</spring_stiffness>
        </dynamics>
      </axis>
    </joint>
    <link name='rear_right_wheel_link'>
      <pose relative_to='rear_right_wheel_joint'>0 0 0 0 -0 0</pose>
      <inertial>
        <pose>0 0 0 1.57079 -0 0</pose>
        <mass>2</mass>
        <inertia>
          <ixx>0.659734</ixx>
          <ixy>0</ixy>
          <ixz>0</ixz>
          <iyy>0.659734</iyy>
          <iyz>0</iyz>
          <izz>1.27235</izz>
        </inertia>
      </inertial>
      <collision name='rear_right_wheel_link_collision'>
        <pose>0 0 0 1.57079 -0 0</pose>
        <geometry>
          <cylinder>
            <length>0.1</length>
            <radius>0.3</radius>
          </cylinder>
        </geometry>
        <surface>
          <contact>
            <ode/>
          </contact>
          <friction>
            <ode>
              <mu>100</mu>
              <mu2>100</mu2>
            </ode>
          </friction>
        </surface>
      </collision>
      <visual name='rear_right_wheel_link_visual'>
        <pose>0 0 0 1.57079 -0 0</pose>
        <geometry>
          <cylinder>
            <length>0.1</length>
            <radius>0.3</radius>
          </cylinder>
        </geometry>
      </visual>
    </link>
  </model>
</sdf>
