<?xml version="1.0" ?>
<!-- =================================================================================== -->
<!-- |    This document was autogenerated by xacro from robot_challenge_description.xacro | -->
<!-- |    EDITING THIS FILE BY HAND IS NOT RECOMMENDED                                 | -->
<!-- =================================================================================== -->
<robot name="ackermann_steering_vehicle">
  <!-- Links -->
  <!-- Body Link -->
  <link name="base_link">
    <visual>
      <origin rpy="0.0 0.0 0.0" xyz="0.0 0.0 0.0"/>
      <geometry>
        <box size="2.0 1.0 0.5"/>
      </geometry>
      <material name="body_material">
        <color rgba="0.25 0.25 0.25 1.0"/>
      </material>
    </visual>
    <collision>
      <origin rpy="0.0 0.0 0.0" xyz="0.0 0.0 0.0"/>
      <geometry>
        <box size="2.0 1.0 0.5"/>
      </geometry>
    </collision>
  </link>
  <!-- Front Left Wheel -->
  <link name="front_left_wheel_link">
    <visual>
      <origin rpy="1.570795 0.0 0.0" xyz="0.0 0.0 0.0"/>
      <geometry>
        <cylinder length="0.1" radius="0.3"/>
      </geometry>
      <material name="wheel_material">
        <color rgba="0.0 0.0 0.0 1.0"/>
      </material>
    </visual>
    <collision>
      <origin rpy="1.570795 0.0 0.0" xyz="0.0 0.0 0.0"/>
      <geometry>
        <cylinder length="0.1" radius="0.3"/>
      </geometry>
    </collision>
    <inertial>
      <mass value="28.27433385"/>
      <inertia ixx="0.6597344564999998" ixy="0.0" ixz="0.0" iyy="0.6597344564999998" iyz="0" izz="1.27234502325"/>
      <origin rpy="1.570795 0.0 0.0" xyz="0.0 0.0 0.0"/>
    </inertial>
  </link>
  <!-- Front Left Wheel Steering -->
  <link name="front_left_steering_link">
    <visual>
      <origin rpy="1.570795 0.0 0.0" xyz="0.0 0.0 0.0"/>
      <geometry>
        <cylinder length="0.001" radius="0.01"/>
      </geometry>
      <material name="wheel_material">
        <color rgba="0.0 0.0 0.0 1.0"/>
      </material>
    </visual>
    <collision>
      <origin rpy="1.570795 0.0 0.0" xyz="0.0 0.0 0.0"/>
      <geometry>
        <cylinder length="0.001" radius="0.01"/>
      </geometry>
    </collision>
    <inertial>
      <mass value="0.01"/>
      <inertia ixx="0.001" ixy="0.0" ixz="0.0" iyy="0.001" iyz="0.0" izz="0.001"/>
      <origin rpy="1.570795 0.0 0.0" xyz="0.0 0.0 0.0"/>
    </inertial>
  </link>
  <!-- Front Right Wheel -->
  <link name="front_right_wheel_link">
    <visual>
      <origin rpy="1.570795 0.0 0.0" xyz="0.0 0.0 0.0"/>
      <geometry>
        <cylinder length="0.1" radius="0.3"/>
      </geometry>
      <material name="wheel_material">
        <color rgba="0.0 0.0 0.0 1.0"/>
      </material>
    </visual>
    <collision>
      <origin rpy="1.570795 0.0 0.0" xyz="0.0 0.0 0.0"/>
      <geometry>
        <cylinder length="0.1" radius="0.3"/>
      </geometry>
    </collision>
    <inertial>
      <mass value="28.27433385"/>
      <inertia ixx="0.6597344564999998" ixy="0.0" ixz="0.0" iyy="0.6597344564999998" iyz="0" izz="1.27234502325"/>
      <origin rpy="1.570795 0.0 0.0" xyz="0.0 0.0 0.0"/>
    </inertial>
  </link>
  <!-- Front Right Wheel Steering -->
  <link name="front_right_steering_link">
    <visual>
      <origin rpy="1.570795 0.0 0.0" xyz="0.0 0.0 0.0"/>
      <geometry>
        <cylinder length="0.001" radius="0.01"/>
      </geometry>
      <material name="wheel_material">
        <color rgba="0.0 0.0 0.0 1.0"/>
      </material>
    </visual>
    <collision>
      <origin rpy="1.570795 0.0 0.0" xyz="0.0 0.0 0.0"/>
      <geometry>
        <cylinder length="0.001" radius="0.01"/>
      </geometry>
    </collision>
    <inertial>
      <mass value="0.01"/>
      <inertia ixx="0.001" ixy="0.0" ixz="0.0" iyy="0.001" iyz="0.0" izz="0.001"/>
      <origin rpy="1.570795 0.0 0.0" xyz="0.0 0.0 0.0"/>
    </inertial>
  </link>
  <!-- Rear Left Wheel -->
  <link name="rear_left_wheel_link">
    <visual>
      <origin rpy="1.570795 0.0 0.0" xyz="0.0 0.0 0.0"/>
      <geometry>
        <cylinder length="0.1" radius="0.3"/>
      </geometry>
      <material name="wheel_material">
        <color rgba="0.0 0.0 0.0 1.0"/>
      </material>
    </visual>
    <collision>
      <origin rpy="1.570795 0.0 0.0" xyz="0.0 0.0 0.0"/>
      <geometry>
        <cylinder length="0.1" radius="0.3"/>
      </geometry>
    </collision>
    <inertial>
      <mass value="2"/>
      <inertia ixx="0.6597344564999998" ixy="0.0" ixz="0.0" iyy="0.6597344564999998" iyz="0" izz="1.27234502325"/>
      <origin rpy="1.570795 0.0 0.0" xyz="0.0 0.0 0.0"/>
    </inertial>
  </link>
  <!-- Rear Right Wheel -->
  <link name="rear_right_wheel_link">
    <visual>
      <origin rpy="1.570795 0.0 0.0" xyz="0.0 0.0 0.0"/>
      <geometry>
        <cylinder length="0.1" radius="0.3"/>
      </geometry>
      <material name="wheel_material">
        <color rgba="0.0 0.0 0.0 1.0"/>
      </material>
    </visual>
    <collision>
      <origin rpy="1.570795 0.0 0.0" xyz="0.0 0.0 0.0"/>
      <geometry>
        <cylinder length="0.1" radius="0.3"/>
      </geometry>
    </collision>
    <inertial>
      <mass value="2"/>
      <inertia ixx="0.6597344564999998" ixy="0.0" ixz="0.0" iyy="0.6597344564999998" iyz="0" izz="1.27234502325"/>
      <origin rpy="1.570795 0.0 0.0" xyz="0.0 0.0 0.0"/>
    </inertial>
  </link>
  <!-- Camera Stick Link -->
  <link name="camera_stick_link">
    <collision>
      <origin rpy="0 0 0" xyz="0 0 0"/>
      <geometry>
        <box size="0.2 0.2 1.5"/>
      </geometry>
    </collision>
    <visual>
      <origin rpy="0 0 0" xyz="0 0 0"/>
      <geometry>
        <box size="0.2 0.2 1.5"/>
      </geometry>
      <material name="camera_stick_material">
        <color rgba="0.25 0.25 0.25 1.0"/>
      </material>
    </visual>
    <inertial>
      <mass value="1e-5"/>
      <origin rpy="0 0 0" xyz="0 0 0"/>
      <inertia ixx="1e-6" ixy="0" ixz="0" iyy="1e-6" iyz="0" izz="1e-6"/>
    </inertial>
  </link>
  <!-- Camera Link -->
  <link name="camera_link">
    <collision>
      <origin rpy="0 0 0" xyz="0 0 0"/>
      <geometry>
        <box size="0.1 0.1 0.1"/>
      </geometry>
    </collision>
    <visual>
      <origin rpy="0 0 0" xyz="0 0 0"/>
      <geometry>
        <box size="0.1 0.1 0.1"/>
      </geometry>
      <material name="camera_material">
        <color rgba="0.0 0.0 0.0 1.0"/>
      </material>
    </visual>
    <inertial>
      <mass value="1e-5"/>
      <origin rpy="0 0 0" xyz="0 0 0"/>
      <inertia ixx="1e-6" ixy="0" ixz="0" iyy="1e-6" iyz="0" izz="1e-6"/>
    </inertial>
  </link>
  <!-- IMU Link -->
  <link name="imu_link">
    <visual>
      <geometry>
        <box size="0.1 0.1 0.1"/>
      </geometry>
    </visual>
    <collision>
      <geometry>
        <box size="0.1 0.1 0.1"/>
      </geometry>
    </collision>
    <inertia ixx="0.00016666666666666672" ixy="0" ixz="0" iyy="0.00016666666666666672" iyz="0" izz="0.00016666666666666672"/>
  </link>
  <!-- Joints -->
  <!-- Front Left Steering Joint -->
  <joint name="front_left_steering_joint" type="revolute">
    <origin rpy="0 0 0" xyz="0.7 0.55 -0.15"/>
    <parent link="base_link"/>
    <child link="front_left_steering_link"/>
    <axis xyz="0 0 1"/>
    <limit effort="1.0" lower="-0.6108" upper="0.6108" velocity="1.570796"/>
    <dynamics damping="0.1" friction="0.1"/>
  </joint>
  <!-- Front Left Wheel Joint -->
  <joint name="front_left_wheel_joint" type="continuous">
    <origin rpy="0 0 0" xyz="0 0 0"/>
    <parent link="front_left_steering_link"/>
    <child link="front_left_wheel_link"/>
    <axis xyz="0 1 0"/>
    <limit effort="10.0" velocity="3.3333333333333335"/>
    <dynamics damping="0.1" friction="0.1"/>
  </joint>
  <!-- Front Right Steering Joint -->
  <joint name="front_right_steering_joint" type="revolute">
    <origin rpy="0 0 0" xyz="0.7 -0.55 -0.15"/>
    <parent link="base_link"/>
    <child link="front_right_steering_link"/>
    <axis xyz="0 0 1"/>
    <limit effort="1.0" lower="-0.6108" upper="0.6108" velocity="1.570796"/>
    <dynamics damping="0.1" friction="0.1"/>
  </joint>
  <!-- Front Right Wheel Joint -->
  <joint name="front_right_wheel_joint" type="continuous">
    <origin rpy="0 0 0" xyz="0 0 0"/>
    <parent link="front_right_steering_link"/>
    <child link="front_right_wheel_link"/>
    <axis xyz="0 1 0"/>
    <limit effort="10.0" velocity="3.3333333333333335"/>
    <dynamics damping="0.1" friction="0.1"/>
  </joint>
  <!-- Rear Left Wheel Joint -->
  <joint name="rear_left_wheel_joint" type="continuous">
    <origin rpy="0 0 0" xyz="-0.7 0.55 -0.15"/>
    <parent link="base_link"/>
    <child link="rear_left_wheel_link"/>
    <axis xyz="0 1 0"/>
    <limit effort="10.0" velocity="3.3333333333333335"/>
    <dynamics damping="0.1" friction="0.1"/>
  </joint>
  <!-- Rear Right Wheel Joint -->
  <joint name="rear_right_wheel_joint" type="continuous">
    <origin rpy="0 0 0" xyz="-0.7 -0.55 -0.15"/>
    <parent link="base_link"/>
    <child link="rear_right_wheel_link"/>
    <axis xyz="0 1 0"/>
    <limit effort="10.0" velocity="3.3333333333333335"/>
    <dynamics damping="0.1" friction="0.1"/>
  </joint>
  <!-- Camera Stick Joint -->
  <joint name="camera_stick_joint" type="fixed">
    <axis xyz="0 1 0"/>
    <origin rpy="0.0 0.0 0.0" xyz="0.9 0.15000000000000002 0.75"/>
    <parent link="base_link"/>
    <child link="camera_stick_link"/>
  </joint>
  <!-- Camera Joint -->
  <joint name="camera_joint" type="fixed">
    <axis xyz="0 1 0"/>
    <origin rpy="0 0.1 0" xyz="0.0 -0.15000000000000002 0.75"/>
    <origin rpy="0 0.1 0" xyz="0.0 0.0 0.0"/>
    <parent link="camera_stick_link"/>
    <child link="camera_link"/>
  </joint>
  <!-- IMU Joint -->
  <joint name="imu_joint" type="fixed">
    <parent link="camera_link"/>
    <child link="imu_link"/>
    <origin xyz="0 0 0.01"/>
  </joint>
  <!-- Gazebo Parameters -->
  <gazebo reference="base_link">
    <mu1>0.0001</mu1>
    <mu2>0.0001</mu2>
  </gazebo>
  <gazebo reference="front_right_wheel_link">
    <mu1>100.0</mu1>
    gazebo_ackermann_steering_vehicle
    
    <mu2>100.0</mu2>
  </gazebo>
  <gazebo reference="front_left_wheel_link">
    <mu1>100.0</mu1>
    <mu2>100.0</mu2>
  </gazebo>
  <gazebo reference="rear_right_wheel_link">
    <mu1>100.0</mu1>
    <mu2>100.0</mu2>
  </gazebo>
  <gazebo reference="rear_left_wheel_link">
    <mu1>100.0</mu1>
    <mu2>100.0</mu2>
  </gazebo>
  <!-- Gazebo Control -->
  <ros2_control name="control" type="system">
    <hardware>
      <plugin>gz_ros2_control/GazeboSimSystem</plugin>
    </hardware>
    <joint name="front_left_steering_joint">
      <command_interface name="position">
        <param name="min">-0.6108</param>
        <param name="max">0.6108</param>
      </command_interface>
      <state_interface name="position"/>
      <state_interface name="velocity"/>
      <state_interface name="effort"/>
    </joint>
    <joint name="front_right_steering_joint">
      <command_interface name="position">
        <param name="min">-0.6108</param>
        <param name="max">0.6108</param>
      </command_interface>
      <state_interface name="position"/>
      <state_interface name="velocity"/>
      <state_interface name="effort"/>
    </joint>
    <joint name="rear_left_wheel_joint">
      <command_interface name="velocity">
        <param name="min">-3.3333333333333335</param>
        <param name="max">3.3333333333333335</param>
      </command_interface>
      <state_interface name="position"/>
      <state_interface name="velocity"/>
      <state_interface name="effort"/>
    </joint>
    <joint name="rear_right_wheel_joint">
      <command_interface name="velocity">
        gazebo_ackermann_steering_vehicle
        
        <param name="min">-3.3333333333333335</param>
        <param name="max">3.3333333333333335</param>
      </command_interface>
      <state_interface name="position"/>
      <state_interface name="velocity"/>
      <state_interface name="effort"/>
    </joint>
  </ros2_control>
  <!-- Gazebo Plugins -->
  <gazebo>
    <plugin filename="libgazebo_ros_joint_state_publisher.so" name="gz::sim::systems::JointStatePublisher">
      <topic>joint_states</topic>
      <joint_name>front_left_steering_joint</joint_name>
      <joint_name>front_right_steering_joint</joint_name>
      <joint_name>front_left_wheel_joint</joint_name>
      <joint_name>front_right_wheel_joint</joint_name>
      <joint_name>rear_left_wheel_joint</joint_name>
      <joint_name>rear_right_wheel_joint</joint_name>
    </plugin>
    <plugin filename="libgz_ros2_control-system.so" name="gz_ros2_control::GazeboSimROS2ControlPlugin">
      <parameters>/workspaces/Cybertron/robot_challenge_description/install/robot_challenge_description/share/robot_challenge_description/config/gz_ros2_control.yaml</parameters>
    </plugin>
    <!-- <plugin filename="gz-sim-sensors-system" name="gz::sim::systems::Sensors">
      <render_engine>ogre2</render_engine>
    </plugin> -->
  </gazebo>
  <!-- Camera -->
  <gazebo reference="camera_link">
    <sensor name="vehicle_front_camera" type="camera">
      <update_rate>30</update_rate>
      <visualize>true</visualize>
      <topic>camera</topic>
      <camera name="head">
        <horizontal_fov>1.570796</horizontal_fov>
        <image>
          <width>640</width>
          <height>480</height>
          <format>R8G8B8</format>
        </image>
        <clip>
          <near>0.02</near>
          <far>300</far>
        </clip>
        <noise>
          <type>gaussian</type>
          <mean>0.0</mean>
          <stddev>0.007</stddev>
        </noise>
      </camera>
      <plugin filename="libgazebo_ros_camera.so" name="camera_controller">
        <alwaysOn>true</alwaysOn>
        <updateRate>0.0</updateRate>
        <cameraName>vehicle_front_camera</cameraName>
        <frameName>camera_link</frameName>
        <hackBaseline>0.07</hackBaseline>
        <distortionK1>0.0</distortionK1>
        <distortionK2>0.0</distortionK2>
        <distortionK3>0.0</distortionK3>
        <distortionT1>0.0</distortionT1>
        <distortionT2>0.0</distortionT2>
      </plugin>
    </sensor>
  </gazebo>
  <gazebo reference="imu_link">
    <sensor name="imu_sensor" type="imu">
      <plugin filename="libgazebo_ros_imu_sensor.so" name="imu_plugin">
        <ros>
          <namespace>/demo</namespace>
          <remapping>~/out:=imu</remapping>
        </ros>
        <initial_orientation_as_reference>false</initial_orientation_as_reference>
      </plugin>
      <always_on>true</always_on>
      <update_rate>100</update_rate>
      <visualize>true</visualize>
      <imu>
        <angular_velocity>
          <x>
            <noise type="gaussian">
              <mean>0.0</mean>
              <stddev>2e-4</stddev>
              <bias_mean>0.0000075</bias_mean>
              <bias_stddev>0.0000008</bias_stddev>
            </noise>
          </x>
          <y>
            <noise type="gaussian">
              <mean>0.0</mean>
              <stddev>2e-4</stddev>
              <bias_mean>0.0000075</bias_mean>
              <bias_stddev>0.0000008</bias_stddev>
            </noise>
          </y>
          <z>
            <noise type="gaussian">
              <mean>0.0</mean>
              <stddev>2e-4</stddev>
              <bias_mean>0.0000075</bias_mean>
              <bias_stddev>0.0000008</bias_stddev>
            </noise>
          </z>
        </angular_velocity>
        <linear_acceleration>
          <x>
            <noise type="gaussian">
              <mean>0.0</mean>
              <stddev>1.7e-2</stddev>
              <bias_mean>0.1</bias_mean>
              <bias_stddev>0.001</bias_stddev>
            </noise>
          </x>
          <y>
            <noise type="gaussian">
              <mean>0.0</mean>
              <stddev>1.7e-2</stddev>
              <bias_mean>0.1</bias_mean>
              <bias_stddev>0.001</bias_stddev>
            </noise>
          </y>
          <z>
            <noise type="gaussian">
              <mean>0.0</mean>
              <stddev>1.7e-2</stddev>
              <bias_mean>0.1</bias_mean>
              <bias_stddev>0.001</bias_stddev>
            </noise>
          </z>
        </linear_acceleration>
      </imu>
    </sensor>
  </gazebo>
  <gazebo>
    <plugin filename="libgazebo_ros_ackermann_drive.so" name="ackermann_plugin">
      <ros>
        <namespace>ackermann</namespace>
        <remapping>cmd_vel:=cmd_vel</remapping>
        <remapping>odom:=odom</remapping>
        <remapping>distance:=distance</remapping>
      </ros>
      <!-- <left_joint>front_left_wheel_joint</left_joint>
    <left_joint>rear_left_wheel_joint</left_joint>
    <right_joint>front_right_wheel_joint</right_joint>
    <right_joint>rear_right_wheel_joint</right_joint> 
    -->
      <!--
    Docs
    https://docs.ros.org/en/rolling/p/gazebo_plugins/generated/classgazebo__plugins_1_1GazeboRosAckermannDrive.html
    -->
      <left_steering_joint>front_left_steering_joint</left_steering_joint>
      <right_steering_joint>front_right_steering_joint</right_steering_joint>
      <front_right_joint>front_right_wheel_joint</front_right_joint>
      <front_left_joint>front_left_wheel_joint</front_left_joint>
      <rear_right_joint>rear_right_wheel_joint</rear_right_joint>
      <rear_left_joint>rear_left_wheel_joint</rear_left_joint>
      <wheel_separation>1.0</wheel_separation>
      <!-- output -->
      <publish_odom>true</publish_odom>
      <publish_odom_tf>true</publish_odom_tf>
      <publish_wheel_tf>true</publish_wheel_tf>
      <publish_distance>true</publish_distance>
      <odometry_frame>odom_demo</odometry_frame>
      <robot_base_frame>base_link</robot_base_frame>
    </plugin>
  </gazebo>
</robot>
