<sdf version='1.7'>
  <model name='ackermann_steering_vehicle'>
    <link name='base_link'>
      <inertial>
        <pose>-0.232 0 0.069 0 -0 0</pose>
        <mass>2e-05</mass>
        <inertia>
          <ixx>2e-06</ixx>
          <ixy>0</ixy>
          <ixz>5.29396e-23</ixz>
          <iyy>2e-06</iyy>
          <iyz>0</iyz>
          <izz>2e-06</izz>
        </inertia>
      </inertial>
      <collision name='base_link_collision'>
        <pose>0 0 0 0 -0 0</pose>
        <geometry>
          <box>
            <size>0.474 0.192 0.138</size>
          </box>
        </geometry>
        <surface>
          <contact>
            <ode/>
          </contact>
          <friction>
            <ode>
              <mu>0.0001</mu>
              <mu2>0.0001</mu2>
            </ode>
          </friction>
        </surface>
      </collision>
      <collision name='base_link_fixed_joint_lump__camera_stick_link_collision_1'>
        <pose>-0.232 0 0.069 0 -0 0</pose>
        <geometry>
          <box>
            <size>0.01 0.01 0.0254</size>
          </box>
        </geometry>
      </collision>
      <collision name='base_link_fixed_joint_lump__camera_link_collision_2'>
        <pose>-0.232 0 0.069 0 0.1 0</pose>
        <geometry>
          <box>
            <size>0.0254 0.1 0.0254</size>
          </box>
        </geometry>
        <surface>
          <contact>
            <ode/>
          </contact>
          <friction>
            <ode/>
          </friction>
        </surface>
      </collision>
      <collision name='base_link_fixed_joint_lump__imu_link_collision_3'>
        <pose>-0.231002 0 0.07895 0 0.1 0</pose>
        <geometry>
          <box>
            <size>0.0254 0.1 0.0254</size>
          </box>
        </geometry>
        <surface>
          <contact>
            <ode/>
          </contact>
          <friction>
            <ode/>
          </friction>
        </surface>
      </collision>
      <collision name='base_link_fixed_joint_lump__lidar_link_collision_4'>
        <pose>0.222 0 0.0426 0 -0 0</pose>
        <geometry>
          <cylinder>
            <length>0.0528</length>
            <radius>0.0325</radius>
          </cylinder>
        </geometry>
        <surface>
          <contact>
            <ode/>
          </contact>
          <friction>
            <ode/>
          </friction>
        </surface>
      </collision>
      <visual name='base_link_visual'>
        <pose>0 0 0 0 -0 0</pose>
        <geometry>
          <box>
            <size>0.474 0.192 0.138</size>
          </box>
        </geometry>
      </visual>
      <visual name='base_link_fixed_joint_lump__camera_stick_link_visual_1'>
        <pose>-0.232 0 0.069 0 -0 0</pose>
        <geometry>
          <box>
            <size>0.01 0.01 0.0254</size>
          </box>
        </geometry>
      </visual>
      <visual name='base_link_fixed_joint_lump__camera_link_visual_2'>
        <pose>-0.232 0 0.069 0 0.1 0</pose>
        <geometry>
          <box>
            <size>0.0254 0.1 0.0254</size>
          </box>
        </geometry>
      </visual>
      <visual name='base_link_fixed_joint_lump__imu_link_visual_3'>
        <pose>-0.231002 0 0.07895 0 0.1 0</pose>
        <geometry>
          <box>
            <size>0.0254 0.1 0.0254</size>
          </box>
        </geometry>
      </visual>
      <visual name='base_link_fixed_joint_lump__lidar_link_visual_4'>
        <pose>0.222 0 0.0426 0 -0 0</pose>
        <geometry>
          <cylinder>
            <length>0.0528</length>
            <radius>0.0325</radius>
          </cylinder>
        </geometry>
      </visual>
      <sensor name='vehicle_front_camera' type='camera'>
        <update_rate>30</update_rate>
        <visualize>1</visualize>
        <topic>camera</topic>
        <camera name='head'>
          <horizontal_fov>1.5708</horizontal_fov>
          <image>
            <width>640</width>
            <height>480</height>
            <format>R8G8B8</format>
          </image>
          <clip>
            <near>0.02</near>
            <far>300</far>
          </clip>
          <noise>
            <type>gaussian</type>
            <mean>0</mean>
            <stddev>0.007</stddev>
          </noise>
        </camera>
        <plugin name='camera_controller' filename='libgazebo_ros_camera.so'>
          <alwaysOn>1</alwaysOn>
          <updateRate>0.0</updateRate>
          <cameraName>front_camera</cameraName>
          <frameName>camera_link</frameName>
          <hackBaseline>0.07</hackBaseline>
          <distortionK1>0.0</distortionK1>
          <distortionK2>0.0</distortionK2>
          <distortionK3>0.0</distortionK3>
          <distortionT1>0.0</distortionT1>
          <distortionT2>0.0</distortionT2>
        </plugin>
        <pose>-0.232 0 0.069 0 0.1 0</pose>
      </sensor>
      <sensor name='imu_sensor' type='imu'>
        <plugin name='imu_plugin' filename='libgazebo_ros_imu_sensor.so'>
          <ros>
            <namespace>/sensors</namespace>
            <remapping>~/out:=imu</remapping>
          </ros>
          <initial_orientation_as_reference>0</initial_orientation_as_reference>
        </plugin>
        <always_on>1</always_on>
        <update_rate>100</update_rate>
        <visualize>1</visualize>
        <imu>
          <angular_velocity>
            <x>
              <noise type='gaussian'>
                <mean>0</mean>
                <stddev>0.0002</stddev>
                <bias_mean>7.5e-06</bias_mean>
                <bias_stddev>8e-07</bias_stddev>
              </noise>
            </x>
            <y>
              <noise type='gaussian'>
                <mean>0</mean>
                <stddev>0.0002</stddev>
                <bias_mean>7.5e-06</bias_mean>
                <bias_stddev>8e-07</bias_stddev>
              </noise>
            </y>
            <z>
              <noise type='gaussian'>
                <mean>0</mean>
                <stddev>0.0002</stddev>
                <bias_mean>7.5e-06</bias_mean>
                <bias_stddev>8e-07</bias_stddev>
              </noise>
            </z>
          </angular_velocity>
          <linear_acceleration>
            <x>
              <noise type='gaussian'>
                <mean>0</mean>
                <stddev>0.017</stddev>
                <bias_mean>0.1</bias_mean>
                <bias_stddev>0.001</bias_stddev>
              </noise>
            </x>
            <y>
              <noise type='gaussian'>
                <mean>0</mean>
                <stddev>0.017</stddev>
                <bias_mean>0.1</bias_mean>
                <bias_stddev>0.001</bias_stddev>
              </noise>
            </y>
            <z>
              <noise type='gaussian'>
                <mean>0</mean>
                <stddev>0.017</stddev>
                <bias_mean>0.1</bias_mean>
                <bias_stddev>0.001</bias_stddev>
              </noise>
            </z>
          </linear_acceleration>
        </imu>
        <pose>-0.231002 0 0.07895 0 0.1 0</pose>
      </sensor>
      <sensor name='lidar_sensor' type='ray'>
        <update_rate>10</update_rate>
        <ray>
          <scan>
            <horizontal>
              <samples>500</samples>
              <resolution>1</resolution>
              <min_angle>-3.142</min_angle>
              <max_angle>3.142</max_angle>
            </horizontal>
            <vertical>
              <samples>1</samples>
              <resolution>1</resolution>
              <min_angle>0</min_angle>
              <max_angle>0</max_angle>
            </vertical>
          </scan>
          <range>
            <min>0.3</min>
            <max>40</max>
            <resolution>0.001</resolution>
          </range>
          <noise>
            <type>gaussian</type>
            <mean>0</mean>
            <stddev>0</stddev>
          </noise>
        </ray>
        <plugin name='gazebo_ros_laser_controller' filename='libgazebo_ros_ray_sensor.so'>
          <ros>
            <namespace>/sensors</namespace>
            <remapping>~/out:=scan</remapping>
          </ros>
          <frame_name>lidar_link</frame_name>
          <output_type>sensor_msgs/LaserScan</output_type>
          <topic>scan</topic>
          <min_range>0.3</min_range>
          <max_range>40.0</max_range>
          <gaussian_noise>0.008</gaussian_noise>
        </plugin>
        <pose>0.222 0 0.0426 0 -0 0</pose>
      </sensor>
    </link>
    <joint name='front_left_steering_joint' type='revolute'>
      <pose relative_to='base_link'>0.1795 0.13 -0.069 0 -0 0</pose>
      <parent>base_link</parent>
      <child>front_left_steering_link</child>
      <axis>
        <xyz>0 0 1</xyz>
        <limit>
          <lower>-0.6108</lower>
          <upper>0.6108</upper>
          <effort>1</effort>
          <velocity>1.5708</velocity>
        </limit>
        <dynamics>
          <damping>0.1</damping>
          <friction>0.1</friction>
          <spring_reference>0</spring_reference>
          <spring_stiffness>0</spring_stiffness>
        </dynamics>
      </axis>
    </joint>
    <link name='front_left_steering_link'>
      <pose relative_to='front_left_steering_joint'>0 0 0 0 -0 0</pose>
      <inertial>
        <pose>0 0 0 1.57079 -0 0</pose>
        <mass>0.01</mass>
        <inertia>
          <ixx>0.001</ixx>
          <ixy>0</ixy>
          <ixz>0</ixz>
          <iyy>0.001</iyy>
          <iyz>0</iyz>
          <izz>0.001</izz>
        </inertia>
      </inertial>
      <collision name='front_left_steering_link_collision'>
        <pose>0 0 0 1.57079 -0 0</pose>
        <geometry>
          <cylinder>
            <length>0.001</length>
            <radius>0.01</radius>
          </cylinder>
        </geometry>
      </collision>
      <visual name='front_left_steering_link_visual'>
        <pose>0 0 0 1.57079 -0 0</pose>
        <geometry>
          <cylinder>
            <length>0.001</length>
            <radius>0.01</radius>
          </cylinder>
        </geometry>
      </visual>
    </link>
    <joint name='front_left_wheel_joint' type='revolute'>
      <pose relative_to='front_left_steering_link'>0 0 0 0 -0 0</pose>
      <parent>front_left_steering_link</parent>
      <child>front_left_wheel_link</child>
      <axis>
        <xyz>0 1 0</xyz>
        <limit>
          <effort>10</effort>
          <velocity>17.3913</velocity>
          <lower>-1e+16</lower>
          <upper>1e+16</upper>
        </limit>
        <dynamics>
          <damping>0.1</damping>
          <friction>0.1</friction>
          <spring_reference>0</spring_reference>
          <spring_stiffness>0</spring_stiffness>
        </dynamics>
      </axis>
    </joint>
    <link name='front_left_wheel_link'>
      <pose relative_to='front_left_wheel_joint'>0 0 0 0 -0 0</pose>
      <inertial>
        <pose>0 0 0 1.57079 -0 0</pose>
        <mass>0.706309</mass>
        <inertia>
          <ixx>0.000855972</ixx>
          <ixy>0</ixy>
          <ixz>0</ixz>
          <iyy>0.000855972</iyy>
          <iyz>0</iyz>
          <izz>0.00116762</izz>
        </inertia>
      </inertial>
      <collision name='front_left_wheel_link_collision'>
        <pose>0 0 0 1.57079 -0 0</pose>
        <geometry>
          <cylinder>
            <length>0.068</length>
            <radius>0.0575</radius>
          </cylinder>
        </geometry>
        <surface>
          <contact>
            <ode/>
          </contact>
          <friction>
            <ode>
              <mu>100</mu>
              <mu2>100</mu2>
            </ode>
          </friction>
        </surface>
      </collision>
      <visual name='front_left_wheel_link_visual'>
        <pose>0 0 0 1.57079 -0 0</pose>
        <geometry>
          <cylinder>
            <length>0.068</length>
            <radius>0.0575</radius>
          </cylinder>
        </geometry>
      </visual>
    </link>
    <joint name='front_right_steering_joint' type='revolute'>
      <pose relative_to='base_link'>0.1795 -0.13 -0.069 0 -0 0</pose>
      <parent>base_link</parent>
      <child>front_right_steering_link</child>
      <axis>
        <xyz>0 0 1</xyz>
        <limit>
          <lower>-0.6108</lower>
          <upper>0.6108</upper>
          <effort>1</effort>
          <velocity>1.5708</velocity>
        </limit>
        <dynamics>
          <damping>0.1</damping>
          <friction>0.1</friction>
          <spring_reference>0</spring_reference>
          <spring_stiffness>0</spring_stiffness>
        </dynamics>
      </axis>
    </joint>
    <link name='front_right_steering_link'>
      <pose relative_to='front_right_steering_joint'>0 0 0 0 -0 0</pose>
      <inertial>
        <pose>0 0 0 1.57079 -0 0</pose>
        <mass>0.01</mass>
        <inertia>
          <ixx>0.001</ixx>
          <ixy>0</ixy>
          <ixz>0</ixz>
          <iyy>0.001</iyy>
          <iyz>0</iyz>
          <izz>0.001</izz>
        </inertia>
      </inertial>
      <collision name='front_right_steering_link_collision'>
        <pose>0 0 0 1.57079 -0 0</pose>
        <geometry>
          <cylinder>
            <length>0.001</length>
            <radius>0.01</radius>
          </cylinder>
        </geometry>
      </collision>
      <visual name='front_right_steering_link_visual'>
        <pose>0 0 0 1.57079 -0 0</pose>
        <geometry>
          <cylinder>
            <length>0.001</length>
            <radius>0.01</radius>
          </cylinder>
        </geometry>
      </visual>
    </link>
    <joint name='front_right_wheel_joint' type='revolute'>
      <pose relative_to='front_right_steering_link'>0 0 0 0 -0 0</pose>
      <parent>front_right_steering_link</parent>
      <child>front_right_wheel_link</child>
      <axis>
        <xyz>0 1 0</xyz>
        <limit>
          <effort>10</effort>
          <velocity>17.3913</velocity>
          <lower>-1e+16</lower>
          <upper>1e+16</upper>
        </limit>
        <dynamics>
          <damping>0.1</damping>
          <friction>0.1</friction>
          <spring_reference>0</spring_reference>
          <spring_stiffness>0</spring_stiffness>
        </dynamics>
      </axis>
    </joint>
    <link name='front_right_wheel_link'>
      <pose relative_to='front_right_wheel_joint'>0 0 0 0 -0 0</pose>
      <inertial>
        <pose>0 0 0 1.57079 -0 0</pose>
        <mass>0.706309</mass>
        <inertia>
          <ixx>0.000855972</ixx>
          <ixy>0</ixy>
          <ixz>0</ixz>
          <iyy>0.000855972</iyy>
          <iyz>0</iyz>
          <izz>0.00116762</izz>
        </inertia>
      </inertial>
      <collision name='front_right_wheel_link_collision'>
        <pose>0 0 0 1.57079 -0 0</pose>
        <geometry>
          <cylinder>
            <length>0.068</length>
            <radius>0.0575</radius>
          </cylinder>
        </geometry>
        <surface>
          <contact>
            <ode/>
          </contact>
          <friction>
            <ode>
              <mu>100</mu>
              <mu2>100</mu2>
            </ode>
          </friction>
        </surface>
      </collision>
      <visual name='front_right_wheel_link_visual'>
        <pose>0 0 0 1.57079 -0 0</pose>
        <geometry>
          <cylinder>
            <length>0.068</length>
            <radius>0.0575</radius>
          </cylinder>
        </geometry>
      </visual>
    </link>
    <joint name='rear_left_wheel_joint' type='revolute'>
      <pose relative_to='base_link'>-0.1795 0.13 -0.069 0 -0 0</pose>
      <parent>base_link</parent>
      <child>rear_left_wheel_link</child>
      <axis>
        <xyz>0 1 0</xyz>
        <limit>
          <effort>10</effort>
          <velocity>17.3913</velocity>
          <lower>-1e+16</lower>
          <upper>1e+16</upper>
        </limit>
        <dynamics>
          <damping>0.1</damping>
          <friction>0.1</friction>
          <spring_reference>0</spring_reference>
          <spring_stiffness>0</spring_stiffness>
        </dynamics>
      </axis>
    </joint>
    <link name='rear_left_wheel_link'>
      <pose relative_to='rear_left_wheel_joint'>0 0 0 0 -0 0</pose>
      <inertial>
        <pose>0 0 0 1.57079 -0 0</pose>
        <mass>2</mass>
        <inertia>
          <ixx>0.000855972</ixx>
          <ixy>0</ixy>
          <ixz>0</ixz>
          <iyy>0.000855972</iyy>
          <iyz>0</iyz>
          <izz>0.00116762</izz>
        </inertia>
      </inertial>
      <collision name='rear_left_wheel_link_collision'>
        <pose>0 0 0 1.57079 -0 0</pose>
        <geometry>
          <cylinder>
            <length>0.068</length>
            <radius>0.0575</radius>
          </cylinder>
        </geometry>
        <surface>
          <contact>
            <ode/>
          </contact>
          <friction>
            <ode>
              <mu>100</mu>
              <mu2>100</mu2>
            </ode>
          </friction>
        </surface>
      </collision>
      <visual name='rear_left_wheel_link_visual'>
        <pose>0 0 0 1.57079 -0 0</pose>
        <geometry>
          <cylinder>
            <length>0.068</length>
            <radius>0.0575</radius>
          </cylinder>
        </geometry>
      </visual>
    </link>
    <joint name='rear_right_wheel_joint' type='revolute'>
      <pose relative_to='base_link'>-0.1795 -0.13 -0.069 0 -0 0</pose>
      <parent>base_link</parent>
      <child>rear_right_wheel_link</child>
      <axis>
        <xyz>0 1 0</xyz>
        <limit>
          <effort>10</effort>
          <velocity>17.3913</velocity>
          <lower>-1e+16</lower>
          <upper>1e+16</upper>
        </limit>
        <dynamics>
          <damping>0.1</damping>
          <friction>0.1</friction>
          <spring_reference>0</spring_reference>
          <spring_stiffness>0</spring_stiffness>
        </dynamics>
      </axis>
    </joint>
    <link name='rear_right_wheel_link'>
      <pose relative_to='rear_right_wheel_joint'>0 0 0 0 -0 0</pose>
      <inertial>
        <pose>0 0 0 1.57079 -0 0</pose>
        <mass>2</mass>
        <inertia>
          <ixx>0.000855972</ixx>
          <ixy>0</ixy>
          <ixz>0</ixz>
          <iyy>0.000855972</iyy>
          <iyz>0</iyz>
          <izz>0.00116762</izz>
        </inertia>
      </inertial>
      <collision name='rear_right_wheel_link_collision'>
        <pose>0 0 0 1.57079 -0 0</pose>
        <geometry>
          <cylinder>
            <length>0.068</length>
            <radius>0.0575</radius>
          </cylinder>
        </geometry>
        <surface>
          <contact>
            <ode/>
          </contact>
          <friction>
            <ode>
              <mu>100</mu>
              <mu2>100</mu2>
            </ode>
          </friction>
        </surface>
      </collision>
      <visual name='rear_right_wheel_link_visual'>
        <pose>0 0 0 1.57079 -0 0</pose>
        <geometry>
          <cylinder>
            <length>0.068</length>
            <radius>0.0575</radius>
          </cylinder>
        </geometry>
      </visual>
    </link>
    <plugin name='gz::sim::systems::JointStatePublisher' filename='libgazebo_ros_joint_state_publisher.so'>
      <topic>joint_states</topic>
      <joint_name>front_left_steering_joint</joint_name>
      <joint_name>front_right_steering_joint</joint_name>
      <joint_name>front_left_wheel_joint</joint_name>
      <joint_name>front_right_wheel_joint</joint_name>
      <joint_name>rear_left_wheel_joint</joint_name>
      <joint_name>rear_right_wheel_joint</joint_name>
    </plugin>
    <plugin name='gz_ros2_control::GazeboSimROS2ControlPlugin' filename='libgz_ros2_control-system.so'>
      <parameters>/workspaces/Cybertron/robot_challenge_description/install/robot_challenge_description/share/robot_challenge_description/config/gz_ros2_control.yaml</parameters>
    </plugin>
    <static>0</static>
    <plugin name='ackermann_plugin' filename='libgazebo_ros_ackermann_drive.so'>
      <ros>
        <namespace>ackermann</namespace>
        <remapping>cmd_vel:=cmd_vel</remapping>
        <remapping>odom:=odom</remapping>
        <remapping>distance:=distance</remapping>
      </ros>
      <left_steering_joint>front_left_steering_joint</left_steering_joint>
      <right_steering_joint>front_right_steering_joint</right_steering_joint>
      <front_right_joint>front_right_wheel_joint</front_right_joint>
      <front_left_joint>front_left_wheel_joint</front_left_joint>
      <rear_right_joint>rear_right_wheel_joint</rear_right_joint>
      <rear_left_joint>rear_left_wheel_joint</rear_left_joint>
      <steering_wheel_joint>steering_wheel_joint</steering_wheel_joint>
      <wheel_separation>0.192</wheel_separation>
      <publish_odom>1</publish_odom>
      <publish_odom_tf>1</publish_odom_tf>
      <publish_wheel_tf>1</publish_wheel_tf>
      <publish_distance>1</publish_distance>
      <odometry_frame>odom_demo</odometry_frame>
      <robot_base_frame>base_link</robot_base_frame>
    </plugin>
  </model>
</sdf>
