<?xml version="1.0" ?>
<!-- =================================================================================== -->
<!-- |    This document was autogenerated by xacro from src/description/robot_challenge_description.xacro | -->
<!-- |    EDITING THIS FILE BY HAND IS NOT RECOMMENDED                                 | -->
<!-- =================================================================================== -->
<robot name="ackermann_steering_vehicle">
  <!-- <xacro:arg name="camera_length" default=".0254" />
  <xacro:arg name="camera_width" default=".10" />
  <xacro:arg name="camera_height" default="0.0254" />
  <xacro:arg name="lidar_length" default=".10" />
  <xacro:arg name="lidar_width" default=".10" />
  <xacro:arg name="lidar_height" default="0.10" /> -->
  <!-- Materials -->
  <material name="gray_25">
    <color rgba="0.25 0.25 0.25 1.0"/>
  </material>
  <material name="gray_50">
    <color rgba="0.50 0.50 0.50 1.0"/>
  </material>
  <material name="gray_75">
    <color rgba="0.75 0.75 0.75 1.0"/>
  </material>
  <material name="camera_color">
    <color rgba="0.70 0.2 0.2 1.0"/>
  </material>
  <material name="lidar_color">
    <color rgba="0.2 0.7 0.2 1.0"/>
  </material>
  <!-- Links -->
  <!-- Body Link -->
  <link name="base_link">
    <visual>
      <origin rpy="0.0 0.0 0.0" xyz="0.0 0.0 0.0"/>
      <geometry>
        <box size="0.474 0.192 0.138"/>
      </geometry>
      <material name="gray_25"/>
    </visual>
    <collision>
      <origin rpy="0.0 0.0 0.0" xyz="0.0 0.0 0.0"/>
      <geometry>
        <box size="0.474 0.192 0.138"/>
      </geometry>
    </collision>
  </link>
  <!-- Front Left Wheel -->
  <link name="front_left_wheel_link">
    <visual>
      <origin rpy="1.570795 0.0 0.0" xyz="0.0 0.0 0.0"/>
      <geometry>
        <cylinder length="0.068" radius="0.0575"/>
      </geometry>
      <material name="wheel_material">
        <color rgba="0.0 0.0 0.0 1.0"/>
      </material>
    </visual>
    <collision>
      <origin rpy="1.570795 0.0 0.0" xyz="0.0 0.0 0.0"/>
      <geometry>
        <cylinder length="0.068" radius="0.0575"/>
      </geometry>
    </collision>
    <inertial>
      <mass value="0.70630856753625"/>
      <inertia ixx="0.0008559724100448167" ixy="0.0" ixz="0.0" iyy="0.0008559724100448167" iyz="0" izz="0.0011676163507083634"/>
      <origin rpy="1.570795 0.0 0.0" xyz="0.0 0.0 0.0"/>
    </inertial>
  </link>
  <!-- Front Left Wheel Steering -->
  <link name="front_left_steering_link">
    <visual>
      <origin rpy="1.570795 0.0 0.0" xyz="0.0 0.0 0.0"/>
      <geometry>
        <cylinder length="0.001" radius="0.01"/>
      </geometry>
      <material name="wheel_material">
        <color rgba="0.0 0.0 0.0 1.0"/>
      </material>
    </visual>
    <collision>
      <origin rpy="1.570795 0.0 0.0" xyz="0.0 0.0 0.0"/>
      <geometry>
        <cylinder length="0.001" radius="0.01"/>
      </geometry>
    </collision>
    <inertial>
      <mass value="0.01"/>
      <inertia ixx="0.001" ixy="0.0" ixz="0.0" iyy="0.001" iyz="0.0" izz="0.001"/>
      <origin rpy="1.570795 0.0 0.0" xyz="0.0 0.0 0.0"/>
    </inertial>
  </link>
  <!-- Front Right Wheel -->
  <link name="front_right_wheel_link">
    <visual>
      <origin rpy="1.570795 0.0 0.0" xyz="0.0 0.0 0.0"/>
      <geometry>
        <cylinder length="0.068" radius="0.0575"/>
      </geometry>
      <material name="wheel_material">
        <color rgba="0.0 0.0 0.0 1.0"/>
      </material>
    </visual>
    <collision>
      <origin rpy="1.570795 0.0 0.0" xyz="0.0 0.0 0.0"/>
      <geometry>
        <cylinder length="0.068" radius="0.0575"/>
      </geometry>
    </collision>
    <inertial>
      <mass value="0.70630856753625"/>
      <inertia ixx="0.0008559724100448167" ixy="0.0" ixz="0.0" iyy="0.0008559724100448167" iyz="0" izz="0.0011676163507083634"/>
      <origin rpy="1.570795 0.0 0.0" xyz="0.0 0.0 0.0"/>
    </inertial>
  </link>
  <!-- Front Right Wheel Steering -->
  <link name="front_right_steering_link">
    <visual>
      <origin rpy="1.570795 0.0 0.0" xyz="0.0 0.0 0.0"/>
      <geometry>
        <cylinder length="0.001" radius="0.01"/>
      </geometry>
      <material name="wheel_material">
        <color rgba="0.0 0.0 0.0 1.0"/>
      </material>
    </visual>
    <collision>
      <origin rpy="1.570795 0.0 0.0" xyz="0.0 0.0 0.0"/>
      <geometry>
        <cylinder length="0.001" radius="0.01"/>
      </geometry>
    </collision>
    <inertial>
      <mass value="0.01"/>
      <inertia ixx="0.001" ixy="0.0" ixz="0.0" iyy="0.001" iyz="0.0" izz="0.001"/>
      <origin rpy="1.570795 0.0 0.0" xyz="0.0 0.0 0.0"/>
    </inertial>
  </link>
  <!-- Rear Left Wheel -->
  <link name="rear_left_wheel_link">
    <visual>
      <origin rpy="1.570795 0.0 0.0" xyz="0.0 0.0 0.0"/>
      <geometry>
        <cylinder length="0.068" radius="0.0575"/>
      </geometry>
      <material name="wheel_material">
        <color rgba="0.0 0.0 0.0 1.0"/>
      </material>
    </visual>
    <collision>
      <origin rpy="1.570795 0.0 0.0" xyz="0.0 0.0 0.0"/>
      <geometry>
        <cylinder length="0.068" radius="0.0575"/>
      </geometry>
    </collision>
    <inertial>
      <mass value="2"/>
      <inertia ixx="0.0008559724100448167" ixy="0.0" ixz="0.0" iyy="0.0008559724100448167" iyz="0" izz="0.0011676163507083634"/>
      <origin rpy="1.570795 0.0 0.0" xyz="0.0 0.0 0.0"/>
    </inertial>
  </link>
  <!-- Rear Right Wheel -->
  <link name="rear_right_wheel_link">
    <visual>
      <origin rpy="1.570795 0.0 0.0" xyz="0.0 0.0 0.0"/>
      <geometry>
        <cylinder length="0.068" radius="0.0575"/>
      </geometry>
      <material name="wheel_material">
        <color rgba="0.0 0.0 0.0 1.0"/>
      </material>
    </visual>
    <collision>
      <origin rpy="1.570795 0.0 0.0" xyz="0.0 0.0 0.0"/>
      <geometry>
        <cylinder length="0.068" radius="0.0575"/>
      </geometry>
    </collision>
    <inertial>
      <mass value="2"/>
      <inertia ixx="0.0008559724100448167" ixy="0.0" ixz="0.0" iyy="0.0008559724100448167" iyz="0" izz="0.0011676163507083634"/>
      <origin rpy="1.570795 0.0 0.0" xyz="0.0 0.0 0.0"/>
    </inertial>
  </link>
  <!-- Camera Stick Link -->
  <link name="camera_stick_link">
    <collision>
      <origin rpy="0 0 0" xyz="0 0 0"/>
      <geometry>
        <box size="0.01 0.01 0.0254"/>
      </geometry>
    </collision>
    <visual>
      <origin rpy="0 0 0" xyz="0 0 0"/>
      <geometry>
        <box size="0.01 0.01 0.0254"/>
      </geometry>
      <material name="camera_stick_material">
        <color rgba="0.25 0.25 0.25 1.0"/>
      </material>
    </visual>
    <inertial>
      <mass value="1e-5"/>
      <origin rpy="0 0 0" xyz="0 0 0"/>
      <inertia ixx="1e-6" ixy="0" ixz="0" iyy="1e-6" iyz="0" izz="1e-6"/>
    </inertial>
  </link>
  <!-- Camera Link -->
  <link name="camera_link">
    <collision>
      <origin rpy="0 0 0" xyz="0 0 0"/>
      <geometry>
        <box size="0.0254 0.1 0.0254"/>
      </geometry>
    </collision>
    <visual>
      <origin rpy="0 0 0" xyz="0 0 0"/>
      <geometry>
        <box size="0.0254 0.1 0.0254"/>
      </geometry>
      <material name="camera_color"/>
    </visual>
    <inertial>
      <mass value="1e-5"/>
      <origin rpy="0 0 0" xyz="0 0 0"/>
      <inertia ixx="1e-6" ixy="0" ixz="0" iyy="1e-6" iyz="0" izz="1e-6"/>
    </inertial>
  </link>
  <!-- Lidar Link -->
  <link name="lidar_link">
    <collision>
      <origin rpy="0 0 0" xyz="0 0 0"/>
      <geometry>
        <cylinder length="0.0528" radius="0.0325"/>
      </geometry>
    </collision>
    <visual>
      <origin rpy="0 0 0" xyz="0 0 0"/>
      <geometry>
        <cylinder length="0.0528" radius="0.0325"/>
      </geometry>
      <material name="lidar_color"/>
    </visual>
  </link>
  <!-- IMU Link -->
  <link name="imu_link">
    <collision>
      <origin rpy="0 0 0" xyz="0 0 0"/>
      <geometry>
        <box size="0.0254 0.1 0.0254"/>
      </geometry>
    </collision>
    <visual>
      <origin rpy="0 0 0" xyz="0 0 0"/>
      <geometry>
        <box size="0.0254 0.1 0.0254"/>
      </geometry>
    </visual>
    <inertia ixx="0.00016666666666666672" ixy="0" ixz="0" iyy="0.00016666666666666672" iyz="0" izz="0.00016666666666666672"/>
  </link>
  <link name="steering_wheel_link">
  </link>
  <!-- Joints -->
  <!-- Front Left Steering Joint -->
  <joint name="front_left_steering_joint" type="revolute">
    <origin rpy="0 0 0" xyz="0.1795 0.13 -0.069"/>
    <parent link="base_link"/>
    <child link="front_left_steering_link"/>
    <axis xyz="0 0 1"/>
    <limit effort="1.0" lower="-0.6108" upper="0.6108" velocity="1.570796"/>
    <dynamics damping="0.1" friction="0.1"/>
  </joint>
  <!-- Front Left Wheel Joint -->
  <joint name="front_left_wheel_joint" type="continuous">
    <origin rpy="0 0 0" xyz="0 0 0"/>
    <parent link="front_left_steering_link"/>
    <child link="front_left_wheel_link"/>
    <axis xyz="0 1 0"/>
    <limit effort="10.0" velocity="17.391304347826086"/>
    <dynamics damping="0.1" friction="0.1"/>
  </joint>
  <!-- Front Right Steering Joint -->
  <joint name="front_right_steering_joint" type="revolute">
    <origin rpy="0 0 0" xyz="0.1795 -0.13 -0.069"/>
    <parent link="base_link"/>
    <child link="front_right_steering_link"/>
    <axis xyz="0 0 1"/>
    <limit effort="1.0" lower="-0.6108" upper="0.6108" velocity="1.570796"/>
    <dynamics damping="0.1" friction="0.1"/>
  </joint>
  <!-- Front Right Wheel Joint -->
  <joint name="front_right_wheel_joint" type="continuous">
    <origin rpy="0 0 0" xyz="0 0 0"/>
    <parent link="front_right_steering_link"/>
    <child link="front_right_wheel_link"/>
    <axis xyz="0 1 0"/>
    <limit effort="10.0" velocity="17.391304347826086"/>
    <dynamics damping="0.1" friction="0.1"/>
  </joint>
  <!-- Rear Left Wheel Joint -->
  <joint name="rear_left_wheel_joint" type="continuous">
    <origin rpy="0 0 0" xyz="-0.1795 0.13 -0.069"/>
    <parent link="base_link"/>
    <child link="rear_left_wheel_link"/>
    <axis xyz="0 1 0"/>
    <limit effort="10.0" velocity="17.391304347826086"/>
    <dynamics damping="0.1" friction="0.1"/>
  </joint>
  <!-- Rear Right Wheel Joint -->
  <joint name="rear_right_wheel_joint" type="continuous">
    <origin rpy="0 0 0" xyz="-0.1795 -0.13 -0.069"/>
    <parent link="base_link"/>
    <child link="rear_right_wheel_link"/>
    <axis xyz="0 1 0"/>
    <limit effort="10.0" velocity="17.391304347826086"/>
    <dynamics damping="0.1" friction="0.1"/>
  </joint>
  <!-- Camera Stick Joint -->
  <joint name="camera_stick_joint" type="fixed">
    <axis xyz="0 1 0"/>
    <origin rpy="0.0 0.0 0.0" xyz="-0.23199999999999998 0 0.069"/>
    <parent link="base_link"/>
    <child link="camera_stick_link"/>
  </joint>
  <!-- Camera Joint -->
  <joint name="camera_joint" type="fixed">
    <axis xyz="0 1 0"/>
    <!-- <origin xyz="0.0 ${-camera_box_size/2 - camera_stick_size/2} ${camera_height/2}" rpy="0 ${camera_pitch} 0"/> -->
    <origin rpy="0 0.1 0" xyz="0.0 0.0 0.0"/>
    <parent link="camera_stick_link"/>
    <child link="camera_link"/>
  </joint>
  <!-- Lidar Joint -->
  <joint name="lidar_joint" type="fixed">
    <axis xyz="0 1 0"/>
    <origin rpy="0.0 0.0 0.0" xyz="0.237 0 0.042600000000000006"/>
    <parent link="base_link"/>
    <child link="lidar_link"/>
  </joint>
  <!-- IMU Joint -->
  <joint name="imu_joint" type="fixed">
    <parent link="camera_link"/>
    <child link="imu_link"/>
    <origin xyz="0 0 0.01"/>
  </joint>
  <joint name="steering_wheel_joint" type="continuous">
    <parent link="base_link"/>
    <child link="steering_wheel_link"/>
    <origin xyz="0 0 0.0"/>
  </joint>
  <!-- Gazebo Parameters -->
  <gazebo reference="base_link">
    <mu1>0.0001</mu1>
    <mu2>0.0001</mu2>
  </gazebo>
  <gazebo reference="front_right_wheel_link">
    <mu1>100.0</mu1>
    gazebo_ackermann_steering_vehicle
    
    <mu2>100.0</mu2>
  </gazebo>
  <gazebo reference="front_left_wheel_link">
    <mu1>100.0</mu1>
    <mu2>100.0</mu2>
  </gazebo>
  <gazebo reference="rear_right_wheel_link">
    <mu1>100.0</mu1>
    <mu2>100.0</mu2>
  </gazebo>
  <gazebo reference="rear_left_wheel_link">
    <mu1>100.0</mu1>
    <mu2>100.0</mu2>
  </gazebo>
  <!-- Gazebo Control -->
  <ros2_control name="control" type="system">
    <hardware>
      <plugin>gz_ros2_control/GazeboSimSystem</plugin>
    </hardware>
    <joint name="front_left_steering_joint">
      <command_interface name="position">
        <param name="min">-0.6108</param>
        <param name="max">0.6108</param>
      </command_interface>
      <state_interface name="position"/>
      <state_interface name="velocity"/>
      <state_interface name="effort"/>
    </joint>
    <joint name="front_right_steering_joint">
      <command_interface name="position">
        <param name="min">-0.6108</param>
        <param name="max">0.6108</param>
      </command_interface>
      <state_interface name="position"/>
      <state_interface name="velocity"/>
      <state_interface name="effort"/>
    </joint>
    <joint name="rear_left_wheel_joint">
      <command_interface name="velocity">
        <param name="min">-17.391304347826086</param>
        <param name="max">17.391304347826086</param>
      </command_interface>
      <state_interface name="position"/>
      <state_interface name="velocity"/>
      <state_interface name="effort"/>
    </joint>
    <joint name="rear_right_wheel_joint">
      <command_interface name="velocity">
        <param name="min">-17.391304347826086</param>
        <param name="max">17.391304347826086</param>
      </command_interface>
      <state_interface name="position"/>
      <state_interface name="velocity"/>
      <state_interface name="effort"/>
    </joint>
    <joint name="steering_wheel_joint">
    </joint>
  </ros2_control>
  <!-- Gazebo Plugins -->
  <gazebo>
    <plugin filename="libgazebo_ros_joint_state_publisher.so" name="gz::sim::systems::JointStatePublisher">
      <topic>joint_states</topic>
      <joint_name>front_left_steering_joint</joint_name>
      <joint_name>front_right_steering_joint</joint_name>
      <joint_name>front_left_wheel_joint</joint_name>
      <joint_name>front_right_wheel_joint</joint_name>
      <joint_name>rear_left_wheel_joint</joint_name>
      <joint_name>rear_right_wheel_joint</joint_name>
    </plugin>
    <plugin filename="libgz_ros2_control-system.so" name="gz_ros2_control::GazeboSimROS2ControlPlugin">
      <parameters>/workspaces/Cybertron/robot_challenge_description/install/robot_challenge_description/share/robot_challenge_description/config/gz_ros2_control.yaml</parameters>
    </plugin>
    <!-- <plugin filename="gz-sim-sensors-system" name="gz::sim::systems::Sensors">
      <render_engine>ogre2</render_engine>
    </plugin> -->
  </gazebo>
  <!-- Camera -->
  <gazebo reference="camera_link">
    <sensor name="vehicle_front_camera" type="camera">
      <update_rate>30</update_rate>
      <visualize>true</visualize>
      <topic>camera</topic>
      <camera name="head">
        <horizontal_fov>1.570796</horizontal_fov>
        <image>
          <width>640</width>
          <height>480</height>
          <format>R8G8B8</format>
        </image>
        <clip>
          <near>0.02</near>
          <far>300</far>
        </clip>
        <noise>
          <type>gaussian</type>
          <mean>0.0</mean>
          <stddev>0.007</stddev>
        </noise>
      </camera>
      <plugin filename="libgazebo_ros_camera.so" name="camera_controller">
        <alwaysOn>true</alwaysOn>
        <updateRate>0.0</updateRate>
        <cameraName>front_camera</cameraName>
        <frameName>camera_link</frameName>
        <hackBaseline>0.07</hackBaseline>
        <distortionK1>0.0</distortionK1>
        <distortionK2>0.0</distortionK2>
        <distortionK3>0.0</distortionK3>
        <distortionT1>0.0</distortionT1>
        <distortionT2>0.0</distortionT2>
      </plugin>
    </sensor>
  </gazebo>
  <gazebo reference="imu_link">
    <sensor name="imu_sensor" type="imu">
      <plugin filename="libgazebo_ros_imu_sensor.so" name="imu_plugin">
        <ros>
          <namespace>/sensors</namespace>
          <remapping>~/out:=imu</remapping>
        </ros>
        <initial_orientation_as_reference>false</initial_orientation_as_reference>
      </plugin>
      <always_on>true</always_on>
      <update_rate>100</update_rate>
      <visualize>true</visualize>
      <imu>
        <angular_velocity>
          <x>
            <noise type="gaussian">
              <mean>0.0</mean>
              <stddev>2e-4</stddev>
              <bias_mean>0.0000075</bias_mean>
              <bias_stddev>0.0000008</bias_stddev>
            </noise>
          </x>
          <y>
            <noise type="gaussian">
              <mean>0.0</mean>
              <stddev>2e-4</stddev>
              <bias_mean>0.0000075</bias_mean>
              <bias_stddev>0.0000008</bias_stddev>
            </noise>
          </y>
          <z>
            <noise type="gaussian">
              <mean>0.0</mean>
              <stddev>2e-4</stddev>
              <bias_mean>0.0000075</bias_mean>
              <bias_stddev>0.0000008</bias_stddev>
            </noise>
          </z>
        </angular_velocity>
        <linear_acceleration>
          <x>
            <noise type="gaussian">
              <mean>0.0</mean>
              <stddev>1.7e-2</stddev>
              <bias_mean>0.1</bias_mean>
              <bias_stddev>0.001</bias_stddev>
            </noise>
          </x>
          <y>
            <noise type="gaussian">
              <mean>0.0</mean>
              <stddev>1.7e-2</stddev>
              <bias_mean>0.1</bias_mean>
              <bias_stddev>0.001</bias_stddev>
            </noise>
          </y>
          <z>
            <noise type="gaussian">
              <mean>0.0</mean>
              <stddev>1.7e-2</stddev>
              <bias_mean>0.1</bias_mean>
              <bias_stddev>0.001</bias_stddev>
            </noise>
          </z>
        </linear_acceleration>
      </imu>
    </sensor>
  </gazebo>
  <gazebo reference="lidar_link">
    <sensor name="lidar_sensor" type="gpu_lidar">
      <pose> 0 0 0 0 0 0 </pose>
      <update_rate>10</update_rate>
      <visualize>true</visualize>
      <ray>
        <scan>
          <horizontal>
            <samples>500</samples>
            <resolution>1</resolution>
            <min_angle>-3.142</min_angle>
            <max_angle>3.142</max_angle>
          </horizontal>
          <vertical>
            <samples>1</samples>
            <resolution>1</resolution>
            <min_angle>0</min_angle>
            <max_angle>0</max_angle>
          </vertical>
        </scan>
        <range>
          <min>0.3</min>
          <max>40.0</max>
          <resolution>0.001</resolution>
        </range>
        <noise>
          <type>gaussian</type>
          <mean>0.0</mean>
          <stddev>0.0</stddev>
        </noise>
      </ray>
      <plugin filename="libgazebo_ros_ray_sensor.so" name="gazebo_ros_laser_controller">
        <ros>
          <namespace>/sensors</namespace>
          <remapping>~/out:=scan</remapping>
        </ros>
        <frame_name>lidar_link</frame_name>
        <output_type>sensor_msgs/LaserScan</output_type>
        <topic>scan</topic>
        <min_range>0.3</min_range>
        <max_range>40.0</max_range>
        <gaussian_noise>0.008</gaussian_noise>
        <always_on>1</always_on>
        <render_engine>ogre2</render_engine>
      </plugin>
    </sensor>
  </gazebo>
  <gazebo>
    <plugin filename="libgazebo_ros_ackermann_drive.so" name="ackermann_plugin">
      <ros>
        <namespace>ackermann</namespace>
        <remapping>cmd_vel:=cmd_vel</remapping>
        <remapping>odom:=odom</remapping>
        <remapping>distance:=distance</remapping>
      </ros>
      <!-- <left_joint>front_left_wheel_joint</left_joint>
    <left_joint>rear_left_wheel_joint</left_joint>
    <right_joint>front_right_wheel_joint</right_joint>
    <right_joint>rear_right_wheel_joint</right_joint> 
    -->
      <!--
    Docs
    https://docs.ros.org/en/rolling/p/gazebo_plugins/generated/classgazebo__plugins_1_1GazeboRosAckermannDrive.html
    -->
      <left_steering_joint>front_left_steering_joint</left_steering_joint>
      <right_steering_joint>front_right_steering_joint</right_steering_joint>
      <front_right_joint>front_right_wheel_joint</front_right_joint>
      <front_left_joint>front_left_wheel_joint</front_left_joint>
      <rear_right_joint>rear_right_wheel_joint</rear_right_joint>
      <rear_left_joint>rear_left_wheel_joint</rear_left_joint>
      <steering_wheel_joint>steering_wheel_joint</steering_wheel_joint>
      <wheel_separation>0.192</wheel_separation>
      <!-- output -->
      <publish_odom>true</publish_odom>
      <publish_odom_tf>true</publish_odom_tf>
      <publish_wheel_tf>true</publish_wheel_tf>
      <publish_distance>true</publish_distance>
      <odometry_frame>odom_demo</odometry_frame>
      <robot_base_frame>base_link</robot_base_frame>
    </plugin>
  </gazebo>
</robot>
