<sdf version='1.9'>
  <model name='ackermann_steering_vehicle'>
    <link name='base_link'>
      <inertial>
        <pose>-0.232 0 0.06899999999999999 0 0 0</pose>
        <mass>2.0000000000000002e-05</mass>
        <inertia>
          <ixx>1.9999999999999999e-06</ixx>
          <ixy>0</ixy>
          <ixz>5.2939559203393771e-23</ixz>
          <iyy>1.9999999999999991e-06</iyy>
          <iyz>0</iyz>
          <izz>1.9999999999999999e-06</izz>
        </inertia>
      </inertial>
      <collision name='base_link_fixed_joint_lump__body_link_collision'>
        <pose>0 0 0 0 0 0</pose>
        <geometry>
          <box>
            <size>0.474 0.192 0.138</size>
          </box>
        </geometry>
      </collision>
      <collision name='base_link_fixed_joint_lump__camera_stick_link_collision_1'>
        <pose>-0.232 0 0.06900000000000001 0 0 0</pose>
        <geometry>
          <box>
            <size>0.01 0.01 0.0254</size>
          </box>
        </geometry>
      </collision>
      <collision name='base_link_fixed_joint_lump__camera_link_collision_2'>
        <pose>-0.232 0 0.06900000000000001 0 0.1 0</pose>
        <geometry>
          <box>
            <size>0.0254 0.1 0.0254</size>
          </box>
        </geometry>
        <surface>
          <contact>
            <ode/>
          </contact>
          <friction>
            <ode/>
          </friction>
        </surface>
      </collision>
      <collision name='base_link_fixed_joint_lump__imu_link_collision_3'>
        <pose>-0.2310016658335317 0 0.07895004165278026 0 0.1 0</pose>
        <geometry>
          <box>
            <size>0.0254 0.1 0.0254</size>
          </box>
        </geometry>
        <surface>
          <contact>
            <ode/>
          </contact>
          <friction>
            <ode/>
          </friction>
        </surface>
      </collision>
      <collision name='base_link_fixed_joint_lump__lidar_link_collision_4'>
        <pose>0.237 0 0.04260000000000001 0 0 0</pose>
        <geometry>
          <cylinder>
            <length>0.0528</length>
            <radius>0.032500000000000001</radius>
          </cylinder>
        </geometry>
        <surface>
          <contact>
            <ode/>
          </contact>
          <friction>
            <ode/>
          </friction>
        </surface>
      </collision>
      <visual name='base_link_fixed_joint_lump__body_link_visual'>
        <pose>0 0 0 0 0 0</pose>
        <geometry>
          <box>
            <size>0.474 0.192 0.138</size>
          </box>
        </geometry>
        <material>
          <diffuse>0.9375 0.9375 0.9375 1</diffuse>
          <ambient>0.9375 0.9375 0.9375 1</ambient>
        </material>
      </visual>
      <visual name='base_link_fixed_joint_lump__camera_stick_link_visual_1'>
        <pose>-0.232 0 0.06900000000000001 0 0 0</pose>
        <geometry>
          <box>
            <size>0.01 0.01 0.0254</size>
          </box>
        </geometry>
        <material>
          <diffuse>0.3125 0.3125 0.3125 1</diffuse>
          <ambient>0.3125 0.3125 0.3125 1</ambient>
        </material>
      </visual>
      <visual name='base_link_fixed_joint_lump__camera_link_visual_2'>
        <pose>-0.232 0 0.06900000000000001 0 0.1 0</pose>
        <geometry>
          <box>
            <size>0.0254 0.1 0.0254</size>
          </box>
        </geometry>
        <material>
          <diffuse>0.875 0.25 0.25 1</diffuse>
          <ambient>0.875 0.25 0.25 1</ambient>
        </material>
      </visual>
      <visual name='base_link_fixed_joint_lump__imu_link_visual_3'>
        <pose>-0.2310016658335317 0 0.07895004165278026 0 0.1 0</pose>
        <geometry>
          <box>
            <size>0.0254 0.1 0.0254</size>
          </box>
        </geometry>
      </visual>
      <visual name='base_link_fixed_joint_lump__lidar_link_visual_4'>
        <pose>0.237 0 0.04260000000000001 0 0 0</pose>
        <geometry>
          <cylinder>
            <length>0.0528</length>
            <radius>0.032500000000000001</radius>
          </cylinder>
        </geometry>
        <material>
          <diffuse>0.25 0.875 0.25 1</diffuse>
          <ambient>0.25 0.875 0.25 1</ambient>
        </material>
      </visual>
      <sensor name='vehicle_front_camera' type='camera'>
        <update_rate>30</update_rate>
        <visualize>true</visualize>
        <topic>camera</topic>
        <camera name='head'>
          <horizontal_fov>1.5707960000000001</horizontal_fov>
          <image>
            <width>640</width>
            <height>480</height>
            <format>R8G8B8</format>
          </image>
          <clip>
            <near>0.02</near>
            <far>300</far>
          </clip>
          <noise>
            <type>gaussian</type>
            <mean>0</mean>
            <stddev>0.0070000000000000001</stddev>
          </noise>
        </camera>
        <pose>-0.232 0 0.069 0 0.1 0</pose>
      </sensor>
      <sensor name='imu_sensor' type='imu'>
        <always_on>true</always_on>
        <update_rate>100</update_rate>
        <visualize>true</visualize>
        <imu>
          <angular_velocity>
            <x>
              <noise type='gaussian'>
                <mean>0</mean>
                <stddev>0.00020000000000000001</stddev>
                <bias_mean>7.5000000000000002e-06</bias_mean>
                <bias_stddev>7.9999999999999996e-07</bias_stddev>
              </noise>
            </x>
            <y>
              <noise type='gaussian'>
                <mean>0</mean>
                <stddev>0.00020000000000000001</stddev>
                <bias_mean>7.5000000000000002e-06</bias_mean>
                <bias_stddev>7.9999999999999996e-07</bias_stddev>
              </noise>
            </y>
            <z>
              <noise type='gaussian'>
                <mean>0</mean>
                <stddev>0.00020000000000000001</stddev>
                <bias_mean>7.5000000000000002e-06</bias_mean>
                <bias_stddev>7.9999999999999996e-07</bias_stddev>
              </noise>
            </z>
          </angular_velocity>
          <linear_acceleration>
            <x>
              <noise type='gaussian'>
                <mean>0</mean>
                <stddev>0.017000000000000001</stddev>
                <bias_mean>0.10000000000000001</bias_mean>
                <bias_stddev>0.001</bias_stddev>
              </noise>
            </x>
            <y>
              <noise type='gaussian'>
                <mean>0</mean>
                <stddev>0.017000000000000001</stddev>
                <bias_mean>0.10000000000000001</bias_mean>
                <bias_stddev>0.001</bias_stddev>
              </noise>
            </y>
            <z>
              <noise type='gaussian'>
                <mean>0</mean>
                <stddev>0.017000000000000001</stddev>
                <bias_mean>0.10000000000000001</bias_mean>
                <bias_stddev>0.001</bias_stddev>
              </noise>
            </z>
          </linear_acceleration>
        </imu>
        <pose>-0.231002 0 0.07895 0 0.1 0</pose>
      </sensor>
      <sensor name='lidar_sensor' type='gpu_lidar'>
        <update_rate>10</update_rate>
        <topic>LaserScan</topic>
        <always_on>true</always_on>
        <visualize>true</visualize>
        <ray>
          <scan>
            <horizontal>
              <samples>500</samples>
              <resolution>1</resolution>
              <min_angle>-3.1419999999999999</min_angle>
              <max_angle>3.1419999999999999</max_angle>
            </horizontal>
            <vertical>
              <samples>1</samples>
              <resolution>1</resolution>
              <min_angle>0</min_angle>
              <max_angle>0</max_angle>
            </vertical>
          </scan>
          <range>
            <min>0.29999999999999999</min>
            <max>40</max>
            <resolution>0.001</resolution>
          </range>
          <noise>
            <type>gaussian</type>
            <mean>0</mean>
            <stddev>0</stddev>
          </noise>
        </ray>
        <pose>0.237 0 0.0426 0 -0 0</pose>
      </sensor>
    </link>
    <joint name='front_left_steering_joint' type='revolute'>
      <pose relative_to='base_link'>0.1795 0.13 -0.06900000000000001 0 0 0</pose>
      <parent>base_link</parent>
      <child>front_left_steering_link</child>
      <axis>
        <xyz>0 0 1</xyz>
        <limit>
          <lower>-0.61080000000000001</lower>
          <upper>0.61080000000000001</upper>
          <effort>1</effort>
          <velocity>1.5707960000000001</velocity>
        </limit>
        <dynamics>
          <damping>0.10000000000000001</damping>
          <friction>0.10000000000000001</friction>
          <spring_reference>0</spring_reference>
          <spring_stiffness>0</spring_stiffness>
        </dynamics>
      </axis>
    </joint>
    <link name='front_left_steering_link'>
      <pose relative_to='front_left_steering_joint'>0 0 0 0 0 0</pose>
      <inertial>
        <pose>0 0 0 1.570795 0 0</pose>
        <mass>0.01</mass>
        <inertia>
          <ixx>0.001</ixx>
          <ixy>0</ixy>
          <ixz>0</ixz>
          <iyy>0.001</iyy>
          <iyz>0</iyz>
          <izz>0.001</izz>
        </inertia>
      </inertial>
      <collision name='front_left_steering_link_collision'>
        <pose>0 0 0 1.570795 0 0</pose>
        <geometry>
          <cylinder>
            <length>0.001</length>
            <radius>0.01</radius>
          </cylinder>
        </geometry>
      </collision>
      <visual name='front_left_steering_link_visual'>
        <pose>0 0 0 1.570795 0 0</pose>
        <geometry>
          <cylinder>
            <length>0.001</length>
            <radius>0.01</radius>
          </cylinder>
        </geometry>
        <material>
          <diffuse>0 0 0 1</diffuse>
          <ambient>0 0 0 1</ambient>
        </material>
      </visual>
    </link>
    <joint name='front_left_wheel_joint' type='revolute'>
      <pose relative_to='front_left_steering_link'>0 0 0 0 0 0</pose>
      <parent>front_left_steering_link</parent>
      <child>front_left_wheel_link</child>
      <axis>
        <xyz>0 1 0</xyz>
        <limit>
          <effort>10</effort>
          <velocity>17.39130434782609</velocity>
          <lower>-10000000000000000</lower>
          <upper>10000000000000000</upper>
        </limit>
        <dynamics>
          <damping>0.10000000000000001</damping>
          <friction>0.10000000000000001</friction>
          <spring_reference>0</spring_reference>
          <spring_stiffness>0</spring_stiffness>
        </dynamics>
      </axis>
    </joint>
    <link name='front_left_wheel_link'>
      <pose relative_to='front_left_wheel_joint'>0 0 0 0 0 0</pose>
      <inertial>
        <pose>0 0 0 1.570795 0 0</pose>
        <mass>0.70630856753625004</mass>
        <inertia>
          <ixx>0.00085597241004481666</ixx>
          <ixy>0</ixy>
          <ixz>0</ixz>
          <iyy>0.00085597241004481666</iyy>
          <iyz>0</iyz>
          <izz>0.001167616350708363</izz>
        </inertia>
      </inertial>
      <collision name='front_left_wheel_link_collision'>
        <pose>0 0 0 1.570795 0 0</pose>
        <geometry>
          <cylinder>
            <length>0.068000000000000005</length>
            <radius>0.057500000000000002</radius>
          </cylinder>
        </geometry>
        <surface>
          <contact>
            <ode/>
          </contact>
          <friction>
            <ode>
              <mu>100</mu>
              <mu2>100</mu2>
            </ode>
          </friction>
        </surface>
      </collision>
      <visual name='front_left_wheel_link_visual'>
        <pose>0 0 0 1.570795 0 0</pose>
        <geometry>
          <cylinder>
            <length>0.068000000000000005</length>
            <radius>0.057500000000000002</radius>
          </cylinder>
        </geometry>
        <material>
          <diffuse>0 0 0 1</diffuse>
          <ambient>0 0 0 1</ambient>
        </material>
      </visual>
    </link>
    <joint name='front_right_steering_joint' type='revolute'>
      <pose relative_to='base_link'>0.1795 -0.13 -0.06900000000000001 0 0 0</pose>
      <parent>base_link</parent>
      <child>front_right_steering_link</child>
      <axis>
        <xyz>0 0 1</xyz>
        <limit>
          <lower>-0.61080000000000001</lower>
          <upper>0.61080000000000001</upper>
          <effort>1</effort>
          <velocity>1.5707960000000001</velocity>
        </limit>
        <dynamics>
          <damping>0.10000000000000001</damping>
          <friction>0.10000000000000001</friction>
          <spring_reference>0</spring_reference>
          <spring_stiffness>0</spring_stiffness>
        </dynamics>
      </axis>
    </joint>
    <link name='front_right_steering_link'>
      <pose relative_to='front_right_steering_joint'>0 0 0 0 0 0</pose>
      <inertial>
        <pose>0 0 0 1.570795 0 0</pose>
        <mass>0.01</mass>
        <inertia>
          <ixx>0.001</ixx>
          <ixy>0</ixy>
          <ixz>0</ixz>
          <iyy>0.001</iyy>
          <iyz>0</iyz>
          <izz>0.001</izz>
        </inertia>
      </inertial>
      <collision name='front_right_steering_link_collision'>
        <pose>0 0 0 1.570795 0 0</pose>
        <geometry>
          <cylinder>
            <length>0.001</length>
            <radius>0.01</radius>
          </cylinder>
        </geometry>
      </collision>
      <visual name='front_right_steering_link_visual'>
        <pose>0 0 0 1.570795 0 0</pose>
        <geometry>
          <cylinder>
            <length>0.001</length>
            <radius>0.01</radius>
          </cylinder>
        </geometry>
        <material>
          <diffuse>0 0 0 1</diffuse>
          <ambient>0 0 0 1</ambient>
        </material>
      </visual>
    </link>
    <joint name='front_right_wheel_joint' type='revolute'>
      <pose relative_to='front_right_steering_link'>0 0 0 0 0 0</pose>
      <parent>front_right_steering_link</parent>
      <child>front_right_wheel_link</child>
      <axis>
        <xyz>0 1 0</xyz>
        <limit>
          <effort>10</effort>
          <velocity>17.39130434782609</velocity>
          <lower>-10000000000000000</lower>
          <upper>10000000000000000</upper>
        </limit>
        <dynamics>
          <damping>0.10000000000000001</damping>
          <friction>0.10000000000000001</friction>
          <spring_reference>0</spring_reference>
          <spring_stiffness>0</spring_stiffness>
        </dynamics>
      </axis>
    </joint>
    <link name='front_right_wheel_link'>
      <pose relative_to='front_right_wheel_joint'>0 0 0 0 0 0</pose>
      <inertial>
        <pose>0 0 0 1.570795 0 0</pose>
        <mass>0.70630856753625004</mass>
        <inertia>
          <ixx>0.00085597241004481666</ixx>
          <ixy>0</ixy>
          <ixz>0</ixz>
          <iyy>0.00085597241004481666</iyy>
          <iyz>0</iyz>
          <izz>0.001167616350708363</izz>
        </inertia>
      </inertial>
      <collision name='front_right_wheel_link_collision'>
        <pose>0 0 0 1.570795 0 0</pose>
        <geometry>
          <cylinder>
            <length>0.068000000000000005</length>
            <radius>0.057500000000000002</radius>
          </cylinder>
        </geometry>
        <surface>
          <contact>
            <ode/>
          </contact>
          <friction>
            <ode>
              <mu>100</mu>
              <mu2>100</mu2>
            </ode>
          </friction>
        </surface>
      </collision>
      <visual name='front_right_wheel_link_visual'>
        <pose>0 0 0 1.570795 0 0</pose>
        <geometry>
          <cylinder>
            <length>0.068000000000000005</length>
            <radius>0.057500000000000002</radius>
          </cylinder>
        </geometry>
        <material>
          <diffuse>0 0 0 1</diffuse>
          <ambient>0 0 0 1</ambient>
        </material>
      </visual>
    </link>
    <joint name='rear_left_wheel_joint' type='revolute'>
      <pose relative_to='base_link'>-0.1795 0.13 -0.06900000000000001 0 0 0</pose>
      <parent>base_link</parent>
      <child>rear_left_wheel_link</child>
      <axis>
        <xyz>0 1 0</xyz>
        <limit>
          <effort>10</effort>
          <velocity>17.39130434782609</velocity>
          <lower>-10000000000000000</lower>
          <upper>10000000000000000</upper>
        </limit>
        <dynamics>
          <damping>0.10000000000000001</damping>
          <friction>0.10000000000000001</friction>
          <spring_reference>0</spring_reference>
          <spring_stiffness>0</spring_stiffness>
        </dynamics>
      </axis>
    </joint>
    <link name='rear_left_wheel_link'>
      <pose relative_to='rear_left_wheel_joint'>0 0 0 0 0 0</pose>
      <inertial>
        <pose>0 0 0 1.570795 0 0</pose>
        <mass>2</mass>
        <inertia>
          <ixx>0.00085597241004481666</ixx>
          <ixy>0</ixy>
          <ixz>0</ixz>
          <iyy>0.00085597241004481666</iyy>
          <iyz>0</iyz>
          <izz>0.001167616350708363</izz>
        </inertia>
      </inertial>
      <collision name='rear_left_wheel_link_collision'>
        <pose>0 0 0 1.570795 0 0</pose>
        <geometry>
          <cylinder>
            <length>0.068000000000000005</length>
            <radius>0.057500000000000002</radius>
          </cylinder>
        </geometry>
        <surface>
          <contact>
            <ode/>
          </contact>
          <friction>
            <ode>
              <mu>100</mu>
              <mu2>100</mu2>
            </ode>
          </friction>
        </surface>
      </collision>
      <visual name='rear_left_wheel_link_visual'>
        <pose>0 0 0 1.570795 0 0</pose>
        <geometry>
          <cylinder>
            <length>0.068000000000000005</length>
            <radius>0.057500000000000002</radius>
          </cylinder>
        </geometry>
        <material>
          <diffuse>0 0 0 1</diffuse>
          <ambient>0 0 0 1</ambient>
        </material>
      </visual>
    </link>
    <joint name='rear_right_wheel_joint' type='revolute'>
      <pose relative_to='base_link'>-0.1795 -0.13 -0.06900000000000001 0 0 0</pose>
      <parent>base_link</parent>
      <child>rear_right_wheel_link</child>
      <axis>
        <xyz>0 1 0</xyz>
        <limit>
          <effort>10</effort>
          <velocity>17.39130434782609</velocity>
          <lower>-10000000000000000</lower>
          <upper>10000000000000000</upper>
        </limit>
        <dynamics>
          <damping>0.10000000000000001</damping>
          <friction>0.10000000000000001</friction>
          <spring_reference>0</spring_reference>
          <spring_stiffness>0</spring_stiffness>
        </dynamics>
      </axis>
    </joint>
    <link name='rear_right_wheel_link'>
      <pose relative_to='rear_right_wheel_joint'>0 0 0 0 0 0</pose>
      <inertial>
        <pose>0 0 0 1.570795 0 0</pose>
        <mass>2</mass>
        <inertia>
          <ixx>0.00085597241004481666</ixx>
          <ixy>0</ixy>
          <ixz>0</ixz>
          <iyy>0.00085597241004481666</iyy>
          <iyz>0</iyz>
          <izz>0.001167616350708363</izz>
        </inertia>
      </inertial>
      <collision name='rear_right_wheel_link_collision'>
        <pose>0 0 0 1.570795 0 0</pose>
        <geometry>
          <cylinder>
            <length>0.068000000000000005</length>
            <radius>0.057500000000000002</radius>
          </cylinder>
        </geometry>
        <surface>
          <contact>
            <ode/>
          </contact>
          <friction>
            <ode>
              <mu>100</mu>
              <mu2>100</mu2>
            </ode>
          </friction>
        </surface>
      </collision>
      <visual name='rear_right_wheel_link_visual'>
        <pose>0 0 0 1.570795 0 0</pose>
        <geometry>
          <cylinder>
            <length>0.068000000000000005</length>
            <radius>0.057500000000000002</radius>
          </cylinder>
        </geometry>
        <material>
          <diffuse>0 0 0 1</diffuse>
          <ambient>0 0 0 1</ambient>
        </material>
      </visual>
    </link>
    <joint name='steering_wheel_joint' type='revolute'>
      <pose relative_to='base_link'>0 0 0 0 0 0</pose>
      <parent>base_link</parent>
      <child>steering_wheel_link</child>
      <axis>
        <xyz>1 0 0</xyz>
        <limit>
          <lower>-10000000000000000</lower>
          <upper>10000000000000000</upper>
        </limit>
        <dynamics>
          <spring_reference>0</spring_reference>
          <spring_stiffness>0</spring_stiffness>
        </dynamics>
      </axis>
    </joint>
    <link name='steering_wheel_link'>
      <pose relative_to='steering_wheel_joint'>0 0 0 0 0 0</pose>
      <inertial>
        <pose>0 0 0 0 0 0</pose>
        <mass>1.0000000000000001e-05</mass>
        <inertia>
          <ixx>9.9999999999999995e-07</ixx>
          <ixy>0</ixy>
          <ixz>0</ixz>
          <iyy>9.9999999999999995e-07</iyy>
          <iyz>0</iyz>
          <izz>9.9999999999999995e-07</izz>
        </inertia>
      </inertial>
    </link>
    <plugin name='ignition::gazebo::systems::AckermannSteering' filename='libignition-gazebo-ackermann-steering-system'>
      <left_joint>front_left_wheel_joint</left_joint>
      <left_joint>rear_left_wheel_joint</left_joint>
      <right_joint>front_right_wheel_joint</right_joint>
      <right_joint>rear_right_wheel_joint</right_joint>
      <left_steering_joint>front_left_steering_joint</left_steering_joint>
      <right_steering_joint>front_right_steering_joint</right_steering_joint>
      <kingpin_width>1.0</kingpin_width>
      <steering_limit>0.5</steering_limit>
      <wheel_base>1.0</wheel_base>
      <wheel_separation>1.25</wheel_separation>
      <wheel_radius>0.3</wheel_radius>
      <min_velocity>-1</min_velocity>
      <max_velocity>1</max_velocity>
      <min_acceleration>-3</min_acceleration>
      <max_acceleration>3</max_acceleration>
      <topic>cmd_vel</topic>
    </plugin>
    <plugin name='ignition::gazebo::systems::JointStatePublisher' filename='libignition-gazebo-joint-state-publisher-system.so'>
      <topic>joint_states</topic>
      <update_rate>100</update_rate>
    </plugin>
    <plugin name='gz_ros2_control::GazeboSimROS2ControlPlugin' filename='gz_ros2_control-system'>
      <parameters>/workspaces/Cybertron/robot_challenge_description/install/robot_challenge_description/share/robot_challenge_description/config/gz_ros2_control.yaml</parameters>
    </plugin>
    <frame name='body_joint' attached_to='base_link'>
      <pose>0 0 0 0 -0 0</pose>
    </frame>
    <frame name='body_link' attached_to='body_joint'/>
    <frame name='imu_joint' attached_to='camera_link'>
      <pose>0 0 0.01 0 -0 0</pose>
    </frame>
    <frame name='imu_link' attached_to='imu_joint'/>
    <frame name='camera_joint' attached_to='camera_stick_link'>
      <pose>0 0 0 0 0.1 0</pose>
    </frame>
    <frame name='camera_link' attached_to='camera_joint'/>
    <frame name='camera_stick_joint' attached_to='base_link'>
      <pose>-0.232 0 0.069 0 -0 0</pose>
    </frame>
    <frame name='camera_stick_link' attached_to='camera_stick_joint'/>
    <frame name='lidar_joint' attached_to='base_link'>
      <pose>0.237 0 0.0426 0 -0 0</pose>
    </frame>
    <frame name='lidar_link' attached_to='lidar_joint'/>
  </model>
</sdf>
